Workbook
Name _1._Cot_rectangular_fara_dirijori: [1]Coduri!#REF!
Name _1._Cot_rectangular_fara_dirijori: [2]Coduri!#REF!
Name _1._Cot_rectangular_fara_dirijori: [2]Coduri!#REF!
Name _1._Cot_rectangular_fara_dirijori: Coduri!#REF!
Name _2._Cot_rectangular_fara_dirijori: [1]Coduri!#REF!
Name _2._Cot_rectangular_fara_dirijori: [2]Coduri!#REF!
Name _2._Cot_rectangular_fara_dirijori: [2]Coduri!#REF!
Name _2._Cot_rectangular_fara_dirijori: Coduri!#REF!
Name _5._Piesa_deviatie: [1]Coduri!#REF!
Name _5._Piesa_deviatie: [2]Coduri!#REF!
Name _5._Piesa_deviatie: [2]Coduri!#REF!
Name _5._Piesa_deviatie: Coduri!#REF!
Name ey: Comanda!$B$20

Sheet OPIS
B2: OPIS

Sheet Comanda
B12: De la : Universal Comp Prod
B13: Pentru : RADOIA ISOLIRUNG | E13: Data : 21.03.2023
B14: Subiect : Oferta HVAC HOTEL VALIUG | E14: Numar : xxxx
A16: NOTA DE APROVIZIONARE | C16: Nr./Data | E16: Temko | G16: DENUMIRE PROIECT:
A19: Nr | B19: Eticheta | C19: Sistem | D19: Cod | E19: Dimensiuni | F19: UM | G19: Cant | H19: Suprafata | I19: Grosime | J19: Observatii
A20: =IF(G21=0,"NU","DA") -> DA | B20: Canal drept
A21: 1 | B21: ='Canal drept'!$E6 -> Tubulatura Ventilatie-CRD-1 | C21: ='Canal drept'!$C6 -> Tubulatura Ventilatie | D21: ='Canal drept'!$D6 -> CRD | E21: ='Canal drept'!$I6 -> A=1000;B=300;L=1250 | F21: ='Canal drept'!$J6 -> buc | G21: ='Canal drept'!$K6 -> 50 | H21: ='Canal drept'!$M6 -> 162.5 | I21: ='Canal drept'!$Q6 -> 0.8
A22: 2 | B22: ='Canal drept'!$E7 -> Tubulatura Ventilatie-CRD-2 | C22: ='Canal drept'!$C7 -> Tubulatura Ventilatie | D22: ='Canal drept'!$D7 -> CRD | E22: ='Canal drept'!$I7 -> A=1000;B=300;L=1088 | F22: ='Canal drept'!$J7 -> buc | G22: ='Canal drept'!$K7 -> 1 | H22: ='Canal drept'!$M7 -> 2.8288 | I22: ='Canal drept'!$Q7 -> 0.8
A23: 3 | B23: ='Canal drept'!$E8 -> Tubulatura Ventilatie-CRD-3 | C23: ='Canal drept'!$C8 -> Tubulatura Ventilatie | D23: ='Canal drept'!$D8 -> CRD | E23: ='Canal drept'!$I8 -> A=1000;B=300;L=850 | F23: ='Canal drept'!$J8 -> buc | G23: ='Canal drept'!$K8 -> 2 | H23: ='Canal drept'!$M8 -> 4.42 | I23: ='Canal drept'!$Q8 -> 0.8
A24: 4 | B24: ='Canal drept'!$E9 -> Tubulatura Ventilatie-CRD-4 | C24: ='Canal drept'!$C9 -> Tubulatura Ventilatie | D24: ='Canal drept'!$D9 -> CRD | E24: ='Canal drept'!$I9 -> A=1000;B=300;L=750 | F24: ='Canal drept'!$J9 -> buc | G24: ='Canal drept'!$K9 -> 1 | H24: ='Canal drept'!$M9 -> 1.95 | I24: ='Canal drept'!$Q9 -> 0.8
A25: 5 | B25: ='Canal drept'!$E10 -> Tubulatura Ventilatie-CRD-5 | C25: ='Canal drept'!$C10 -> Tubulatura Ventilatie | D25: ='Canal drept'!$D10 -> CRD | E25: ='Canal drept'!$I10 -> A=1000;B=300;L=700 | F25: ='Canal drept'!$J10 -> buc | G25: ='Canal drept'!$K10 -> 1 | H25: ='Canal drept'!$M10 -> 1.82 | I25: ='Canal drept'!$Q10 -> 0.8
A26: 6 | B26: ='Canal drept'!$E11 -> Tubulatura Ventilatie-CRD-6 | C26: ='Canal drept'!$C11 -> Tubulatura Ventilatie | D26: ='Canal drept'!$D11 -> CRD | E26: ='Canal drept'!$I11 -> A=1000;B=300;L=666 | F26: ='Canal drept'!$J11 -> buc | G26: ='Canal drept'!$K11 -> 4 | H26: ='Canal drept'!$M11 -> 6.9264 | I26: ='Canal drept'!$Q11 -> 0.8
A27: 7 | B27: ='Canal drept'!$E12 -> Tubulatura Ventilatie-CRD-7 | C27: ='Canal drept'!$C12 -> Tubulatura Ventilatie | D27: ='Canal drept'!$D12 -> CRD | E27: ='Canal drept'!$I12 -> A=900;B=300;L=1250 | F27: ='Canal drept'!$J12 -> buc | G27: ='Canal drept'!$K12 -> 6 | H27: ='Canal drept'!$M12 -> 18 | I27: ='Canal drept'!$Q12 -> 0.8
A28: 8 | B28: ='Canal drept'!$E13 -> Tubulatura Ventilatie-CRD-8 | C28: ='Canal drept'!$C13 -> Tubulatura Ventilatie | D28: ='Canal drept'!$D13 -> CRD | E28: ='Canal drept'!$I13 -> A=900;B=300;L=900 | F28: ='Canal drept'!$J13 -> buc | G28: ='Canal drept'!$K13 -> 1 | H28: ='Canal drept'!$M13 -> 2.16 | I28: ='Canal drept'!$Q13 -> 0.8
A29: 9 | B29: ='Canal drept'!$E14 -> Tubulatura Ventilatie-CRD-9 | C29: ='Canal drept'!$C14 -> Tubulatura Ventilatie | D29: ='Canal drept'!$D14 -> CRD | E29: ='Canal drept'!$I14 -> A=900;B=300;L=700 | F29: ='Canal drept'!$J14 -> buc | G29: ='Canal drept'!$K14 -> 1 | H29: ='Canal drept'!$M14 -> 1.68 | I29: ='Canal drept'!$Q14 -> 0.8
A30: 10 | B30: ='Canal drept'!$E15 -> Tubulatura Ventilatie-CRD-10 | C30: ='Canal drept'!$C15 -> Tubulatura Ventilatie | D30: ='Canal drept'!$D15 -> CRD | E30: ='Canal drept'!$I15 -> A=900;B=300;L=238 | F30: ='Canal drept'!$J15 -> buc | G30: ='Canal drept'!$K15 -> 1 | H30: ='Canal drept'!$M15 -> 0.5712 | I30: ='Canal drept'!$Q15 -> 0.8
A31: 11 | B31: ='Canal drept'!$E16 -> Tubulatura Ventilatie-CRD-11 | C31: ='Canal drept'!$C16 -> Tubulatura Ventilatie | D31: ='Canal drept'!$D16 -> CRD | E31: ='Canal drept'!$I16 -> A=800;B=300;L=1250 | F31: ='Canal drept'!$J16 -> buc | G31: ='Canal drept'!$K16 -> 1 | H31: ='Canal drept'!$M16 -> 2.75 | I31: ='Canal drept'!$Q16 -> 0.8
A32: 12 | B32: ='Canal drept'!$E17 -> Tubulatura Ventilatie-CRD-12 | C32: ='Canal drept'!$C17 -> Tubulatura Ventilatie | D32: ='Canal drept'!$D17 -> CRD | E32: ='Canal drept'!$I17 -> A=700;B=300;L=1250 | F32: ='Canal drept'!$J17 -> buc | G32: ='Canal drept'!$K17 -> 1 | H32: ='Canal drept'!$M17 -> 2.5 | I32: ='Canal drept'!$Q17 -> 0.8
... A40: 20 | B40: ='Canal drept'!$E25 -> Tubulatura Ventilatie-CRD-20 | C40: ='Canal drept'!$C25 -> Tubulatura Ventilatie | D40: ='Canal drept'!$D25 -> CRD | E40: ='Canal drept'!$I25 -> A=160;B=300;L=1000 | F40: ='Canal drept'!$J25 -> buc | G40: ='Canal drept'!$K25 -> 1 | H40: ='Canal drept'!$M25 -> 0.92 | I40: ='Canal drept'!$Q25 -> 0.6
A41: =IF(G42=0,"NU","DA") -> DA | B41: Cot rectangular ( fara dirijori ) | C41: 'Cot rectangular'!A1 | D41: 'Cot rectangular'!A1 | E41: 'Cot rectangular'!A1
A42: 1 | B42: ='Cot rectangular'!$E6 -> Tubulatura Ventilatie-CR-1 | C42: ='Cot rectangular'!$C6 -> Tubulatura Ventilatie | D42: ='Cot rectangular'!D6 -> CR | E42: ='Cot rectangular'!K6 -> A1=200; A2 =200; B=300; R =100; < =45 | F42: ='Cot rectangular'!L6 -> buc | G42: ='Cot rectangular'!M6 -> 4 | H42: ='Cot rectangular'!O6 -> 0.73699112 | I42: ='Cot rectangular'!$S6 -> 0.6
A43: 2 | B43: ='Cot rectangular'!$E7 -> Tubulatura Ventilatie-CR-2 | C43: ='Cot rectangular'!$C7 -> Tubulatura Ventilatie | D43: ='Cot rectangular'!D7 -> CR | E43: ='Cot rectangular'!K7 -> A1=900; A2 =900; B=300; R =500; < =90 | F43: ='Cot rectangular'!L7 -> buc | G43: ='Cot rectangular'!M7 -> 1 | H43: ='Cot rectangular'!O7 -> 4.8153539 | I43: ='Cot rectangular'!$S7 -> 0.8
A44: 3 | B44: ='Cot rectangular'!$E8 -> Tubulatura Ventilatie-CR- | C44: ='Cot rectangular'!$C8 -> Tubulatura Ventilatie | D44: ='Cot rectangular'!D8 -> CR | E44: ='Cot rectangular'!K8 -> A1=650; A2 =650; B=300; R =150; < =90 | F44: ='Cot rectangular'!L8 -> buc | G44: ='Cot rectangular'!M8 -> 1 | H44: ='Cot rectangular'!O8 -> 1.727677 | I44: ='Cot rectangular'!$S8 -> 0.8
A45: =IF(G46=0,"NU","DA") -> DA | B45: Reductie simetrica/asimetrica
A46: 1 | B46: ='Reductie simetrica_asim.'!$E6 -> Tubulatura Ventilatie-Red-1 | C46: ='Reductie simetrica_asim.'!$C6 -> Tubulatura Ventilatie | D46: ='Reductie simetrica_asim.'!D6 -> Red | E46: ='Reductie simetrica_asim.'!M6 -> A=1000; B=300; C=900;D=300; e=;f=;L=300 | F46: ='Reductie simetrica_asim.'!N6 -> buc | G46: ='Reductie simetrica_asim.'!O6 -> 1 | H46: ='Reductie simetrica_asim.'!Q6 -> 1.0398683 | I46: ='Reductie simetrica_asim.'!$U6 -> 0.8
A47: 2 | B47: ='Reductie simetrica_asim.'!$E7 -> Tubulatura Ventilatie-Red-2 | C47: ='Reductie simetrica_asim.'!$C7 -> Tubulatura Ventilatie | D47: ='Reductie simetrica_asim.'!D7 -> Red | E47: ='Reductie simetrica_asim.'!M7 -> A=1000; B=300; C=800;D=300; e=;f=;L=300 | F47: ='Reductie simetrica_asim.'!N7 -> buc | G47: ='Reductie simetrica_asim.'!O7 -> 1 | H47: ='Reductie simetrica_asim.'!Q7 -> 1.0081665 | I47: ='Reductie simetrica_asim.'!$U7 -> 0.8
A48: 3 | B48: ='Reductie simetrica_asim.'!$E8 -> Tubulatura Ventilatie-Red-3 | C48: ='Reductie simetrica_asim.'!$C8 -> Tubulatura Ventilatie | D48: ='Reductie simetrica_asim.'!D8 -> Red | E48: ='Reductie simetrica_asim.'!M8 -> A=900; B=300; C=700;D=300; e=;f=;L=300 | F48: ='Reductie simetrica_asim.'!N8 -> buc | G48: ='Reductie simetrica_asim.'!O8 -> 1 | H48: ='Reductie simetrica_asim.'!Q8 -> 0.91816654 | I48: ='Reductie simetrica_asim.'!$U8 -> 0.8
A49: 4 | B49: ='Reductie simetrica_asim.'!$E9 -> Tubulatura Ventilatie-Red-4 | C49: ='Reductie simetrica_asim.'!$C9 -> Tubulatura Ventilatie | D49: ='Reductie simetrica_asim.'!D9 -> Red | E49: ='Reductie simetrica_asim.'!M9 -> A=800; B=300; C=650;D=300; e=;f=;L=300 | F49: ='Reductie simetrica_asim.'!N9 -> buc | G49: ='Reductie simetrica_asim.'!O9 -> 1 | H49: ='Reductie simetrica_asim.'!Q9 -> 0.84312306 | I49: ='Reductie simetrica_asim.'!$U9 -> 0.8
A50: 5 | B50: ='Reductie simetrica_asim.'!$E10 -> Tubulatura Ventilatie-Red-5 | C50: ='Reductie simetrica_asim.'!$C10 -> Tubulatura Ventilatie | D50: ='Reductie simetrica_asim.'!D10 -> Red | E50: ='Reductie simetrica_asim.'!M10 -> A=700; B=300; C=500;D=300; e=;f=;L=300 | F50: ='Reductie simetrica_asim.'!N10 -> buc | G50: ='Reductie simetrica_asim.'!O10 -> 1 | H50: ='Reductie simetrica_asim.'!Q10 -> 0.73816654 | I50: ='Reductie simetrica_asim.'!$U10 -> 0.8
A51: 6 | B51: ='Reductie simetrica_asim.'!$E11 -> Tubulatura Ventilatie-Red-6 | C51: ='Reductie simetrica_asim.'!$C11 -> Tubulatura Ventilatie | D51: ='Reductie simetrica_asim.'!D11 -> Red | E51: ='Reductie simetrica_asim.'!M11 -> A=650; B=300; C=400;D=300; e=;f=;L=300 | F51: ='Reductie simetrica_asim.'!N11 -> buc | G51: ='Reductie simetrica_asim.'!O11 -> 1 | H51: ='Reductie simetrica_asim.'!Q11 -> 0.67965375 | I51: ='Reductie simetrica_asim.'!$U11 -> 0.8
A52: 7 | B52: ='Reductie simetrica_asim.'!$E12 -> Tubulatura Ventilatie-Red-7 | C52: ='Reductie simetrica_asim.'!$C12 -> Tubulatura Ventilatie | D52: ='Reductie simetrica_asim.'!D12 -> Red | E52: ='Reductie simetrica_asim.'!M12 -> A=600; B=300; C=300;D=300; e=;f=;L=300 | F52: ='Reductie simetrica_asim.'!N12 -> buc | G52: ='Reductie simetrica_asim.'!O12 -> 1 | H52: ='Reductie simetrica_asim.'!Q12 -> 0.62227922 | I52: ='Reductie simetrica_asim.'!$U12 -> 0.8
A53: 8 | B53: ='Reductie simetrica_asim.'!$E13 -> Tubulatura Ventilatie-Red-8 | C53: ='Reductie simetrica_asim.'!$C13 -> Tubulatura Ventilatie | D53: ='Reductie simetrica_asim.'!D13 -> Red | E53: ='Reductie simetrica_asim.'!M13 -> A=400; B=300; C=300;D=300; e=;f=;L=300 | F53: ='Reductie simetrica_asim.'!N13 -> buc | G53: ='Reductie simetrica_asim.'!O13 -> 1 | H53: ='Reductie simetrica_asim.'!Q13 -> 0.49986833 | I53: ='Reductie simetrica_asim.'!$U13 -> 0.6
A54: 9 | B54: ='Reductie simetrica_asim.'!$E14 -> Tubulatura Ventilatie-Red-9 | C54: ='Reductie simetrica_asim.'!$C14 -> Tubulatura Ventilatie | D54: ='Reductie simetrica_asim.'!D14 -> Red | E54: ='Reductie simetrica_asim.'!M14 -> A=300; B=300; C=160;D=300; e=;f=;L=300 | F54: ='Reductie simetrica_asim.'!N14 -> buc | G54: ='Reductie simetrica_asim.'!O14 -> 2 | H54: ='Reductie simetrica_asim.'!Q14 -> 0.79263534 | I54: ='Reductie simetrica_asim.'!$U14 -> 0.6
A55: =IF(G56=0,"NU","DA") -> DA | B55: Capac
A56: 1 | B56: =Capac!$E6 -> Tubulatura Ventilatie-Capac-1 | C56: =Capac!$C6 -> Tubulatura Ventilatie | D56: =Capac!D6 -> Capac | E56: =Capac!H6 -> A=300; B=160 | F56: =Capac!I6 -> buc | G56: =Capac!J6 -> 2 | H56: =Capac!L6 -> 0.2 | I56: =Capac!$S6 -> 0.6
A57: =IF(G58=0,"NU","DA") -> DA | B57: Schimbare de sectiune excentrica
D58: SR | E58: Tub Spiro Ø250 L-3000 | F58: buc | G58: 17
D59: ILL | E59: Stut Ø250 | F59: buc | G59: 58
D60: BFL90 | E60: Cot 90⁰ Ø250 | F60: buc | G60: 21
D61: BKFL90 | E61: Cot 90⁰ cu raza redusa Ø250 | F61: buc | G61: 13
...

Sheet Canal drept
R2: Confectie | U2: Organe asamblare | Z2: Sistem prindere
B3: Nr. | C3: Sistem | D3: Cod | E3: Eticheta | F3: DIMENSIUNI | I3: Eticheta dimensiuni | J3: UM | K3: Cant | L3: Sunitar | M3: S | O3: LINK-URI | P3: CONECTARE | Q3: GROSIME [mm] | R3: Flansa [m] | S3: Coltari [buc] | T3: Greutate tabla [kg] | U3: Garnitura etansare [m] | V3: Piulita + Surub M8 [buc] | W3: Piulita + Surub M10 [buc] | X3: Clipsuri [buc] | Y3: Silicon HVAC [buc] | Z3: Piulita expandabila M8 [buc] | AA3: Piulita expandabila M10 [buc] | AB3: Tija filetata M8 [m] | AC3: Tija filetata M10 [m] | AD3: Profil 30x20 [m] | AE3: Profil 41x41 [m] | AF3: Garnitura profil 30x20 [m] | AG3: Garnitura profil 41x41 [m] | AH3: Capac profil 30x20 [buc] | AI3: Capac profil 41x41 [buc]
F4: A | G4: B | H4: L | O4: 'Canal drept'!A1
F5: mm | G5: mm | H5: mm | L5: m2 | M5: m2 | O5: 'Cot rectangular'!A1
B6: 1 | C6: Tubulatura Ventilatie | D6: CRD | E6: =C6&"-"&D6&"-"&B6 -> Tubulatura Ventilatie-CRD-1 | F6: 1000 | G6: 300 | H6: 1250 | I6: =$F$4&"="&$F6&";"&$G$4&"="&$G6&";"&$H$4&"="&$H6 -> A=1000;B=300;L=1250 | J6: buc | K6: 50 | L6: =(2*F6/1000+2*G6/1000)*H6/1000 -> 3.25 | M6: =L6*K6 -> 162.5 | O6: 'Cot rectangular drept'!A1 | P6: =IF((F6+G6)*2>3500,"FLANSA30","FLANSA20") -> FLANSA20 | Q6: =IF(MAX(F6:G6)<=500,"0.6",IF(AND(MAX(F6:G6)>500,MAX(F6:G6)<=1000),"0.8","1.0")) -> 0.8 | R6: =(F6+G6)*4/1000*K6 -> 260 | S6: =K6*4*2 -> 400 | T6: =IF(MAX(F6:G6)<=500,M6*4.71,IF(AND(MAX(F6:G6)>500,MAX(F6:G6)<=1000),M6*6.28,M6*7.85)) -> 1020.5 | U6: =((F6+G6)*2*K6)/1000 -> 130 | V6: =IF(P6="FLANSA20",K6*4,0) -> 200 | W6: =IF(P6="FLANSA30",K6*4,0) -> 0 | X6: =(((F6+G6)*2)*K6)/350 -> 371.42857 | Y6: =K6/18 -> 2.7777778 | Z6: =IF(MAX(F6:G6)<800,(H6*K6/2000)*2,0) -> 0 | AA6: =IF(MAX(F6:G6)>=800,(H6*K6/2000)*2,0) -> 62.5 | AB6: =(G6/1000+0.5)*Z6 -> 0 | AC6: =(G6/1000+0.5)*AA6 -> 50 | AD6: =(F6/1000+0.1)*(Z6/2) -> 0 | AE6: =(F6/1000+0.1)*(AA6/2) -> 34.375 | AF6: =(Z6/2)*0.1 -> 0 | AG6: =(AA6/2)*0.1 -> 3.125 | AH6: =Z6 -> 0 | AI6: =AA6 -> 62.5
B7: 2 | C7: Tubulatura Ventilatie | D7: CRD | E7: =C7&"-"&D7&"-"&B7 -> Tubulatura Ventilatie-CRD-2 | F7: 1000 | G7: 300 | H7: 1088 | I7: =$F$4&"="&$F7&";"&$G$4&"="&$G7&";"&$H$4&"="&$H7 -> A=1000;B=300;L=1088 | J7: buc | K7: 1 | L7: =(2*F7/1000+2*G7/1000)*H7/1000 -> 2.8288 | M7: =L7*K7 -> 2.8288 | O7: 'Cot rectangular cu dirijori'!A1 | P7: =IF((F7+G7)*2>3500,"FLANSA30","FLANSA20") -> FLANSA20 | Q7: =IF(MAX(F7:G7)<=500,"0.6",IF(AND(MAX(F7:G7)>500,MAX(F7:G7)<=1000),"0.8","1.0")) -> 0.8 | R7: =(F7+G7)*4/1000*K7 -> 5.2 | S7: =K7*4*2 -> 8 | T7: =IF(MAX(F7:G7)<=500,M7*4.71,IF(AND(MAX(F7:G7)>500,MAX(F7:G7)<=1000),M7*6.28,M7*7.85)) -> 17.764864 | U7: =((F7+G7)*2*K7)/1000 -> 2.6 | V7: =IF(P7="FLANSA20",K7*4,0) -> 4 | W7: =IF(P7="FLANSA30",K7*4,0) -> 0 | X7: =(((F7+G7)*2)*K7)/350 -> 7.4285714 | Y7: =K7/18 -> 0.055555556 | Z7: =IF(MAX(F7:G7)<800,(H7*K7/2000)*2,0) -> 0 | AA7: =IF(MAX(F7:G7)>=800,(H7*K7/2000)*2,0) -> 1.088 | AB7: =(G7/1000+0.5)*Z7 -> 0 | AC7: =(G7/1000+0.5)*AA7 -> 0.8704 | AD7: =(F7/1000+0.1)*(Z7/2) -> 0 | AE7: =(F7/1000+0.1)*(AA7/2) -> 0.5984 | AF7: =(Z7/2)*0.1 -> 0 | AG7: =(AA7/2)*0.1 -> 0.0544 | AH7: =Z7 -> 0 | AI7: =AA7 -> 1.088
B8: 3 | C8: Tubulatura Ventilatie | D8: CRD | E8: =C8&"-"&D8&"-"&B8 -> Tubulatura Ventilatie-CRD-3 | F8: 1000 | G8: 300 | H8: 850 | I8: =$F$4&"="&$F8&";"&$G$4&"="&$G8&";"&$H$4&"="&$H8 -> A=1000;B=300;L=850 | J8: buc | K8: 2 | L8: =(2*F8/1000+2*G8/1000)*H8/1000 -> 2.21 | M8: =L8*K8 -> 4.42 | O8: Teu!A1 | P8: =IF((F8+G8)*2>3500,"FLANSA30","FLANSA20") -> FLANSA20 | Q8: =IF(MAX(F8:G8)<=500,"0.6",IF(AND(MAX(F8:G8)>500,MAX(F8:G8)<=1000),"0.8","1.0")) -> 0.8 | R8: =(F8+G8)*4/1000*K8 -> 10.4 | S8: =K8*4*2 -> 16 | T8: =IF(MAX(F8:G8)<=500,M8*4.71,IF(AND(MAX(F8:G8)>500,MAX(F8:G8)<=1000),M8*6.28,M8*7.85)) -> 27.7576 | U8: =((F8+G8)*2*K8)/1000 -> 5.2 | V8: =IF(P8="FLANSA20",K8*4,0) -> 8 | W8: =IF(P8="FLANSA30",K8*4,0) -> 0 | X8: =(((F8+G8)*2)*K8)/350 -> 14.857143 | Y8: =K8/18 -> 0.11111111 | Z8: =IF(MAX(F8:G8)<800,(H8*K8/2000)*2,0) -> 0 | AA8: =IF(MAX(F8:G8)>=800,(H8*K8/2000)*2,0) -> 1.7 | AB8: =(G8/1000+0.5)*Z8 -> 0 | AC8: =(G8/1000+0.5)*AA8 -> 1.36 | AD8: =(F8/1000+0.1)*(Z8/2) -> 0 | AE8: =(F8/1000+0.1)*(AA8/2) -> 0.935 | AF8: =(Z8/2)*0.1 -> 0 | AG8: =(AA8/2)*0.1 -> 0.085 | AH8: =Z8 -> 0 | AI8: =AA8 -> 1.7
B9: 4 | C9: Tubulatura Ventilatie | D9: CRD | E9: =C9&"-"&D9&"-"&B9 -> Tubulatura Ventilatie-CRD-4 | F9: 1000 | G9: 300 | H9: 750 | I9: =$F$4&"="&$F9&";"&$G$4&"="&$G9&";"&$H$4&"="&$H9 -> A=1000;B=300;L=750 | J9: buc | K9: 1 | L9: =(2*F9/1000+2*G9/1000)*H9/1000 -> 1.95 | M9: =L9*K9 -> 1.95 | O9: 'Piesa de deviatie (etaj)'!A1 | P9: =IF((F9+G9)*2>3500,"FLANSA30","FLANSA20") -> FLANSA20 | Q9: =IF(MAX(F9:G9)<=500,"0.6",IF(AND(MAX(F9:G9)>500,MAX(F9:G9)<=1000),"0.8","1.0")) -> 0.8 | R9: =(F9+G9)*4/1000*K9 -> 5.2 | S9: =K9*4*2 -> 8 | T9: =IF(MAX(F9:G9)<=500,M9*4.71,IF(AND(MAX(F9:G9)>500,MAX(F9:G9)<=1000),M9*6.28,M9*7.85)) -> 12.246 | U9: =((F9+G9)*2*K9)/1000 -> 2.6 | V9: =IF(P9="FLANSA20",K9*4,0) -> 4 | W9: =IF(P9="FLANSA30",K9*4,0) -> 0 | X9: =(((F9+G9)*2)*K9)/350 -> 7.4285714 | Y9: =K9/18 -> 0.055555556 | Z9: =IF(MAX(F9:G9)<800,(H9*K9/2000)*2,0) -> 0 | AA9: =IF(MAX(F9:G9)>=800,(H9*K9/2000)*2,0) -> 0.75 | AB9: =(G9/1000+0.5)*Z9 -> 0 | AC9: =(G9/1000+0.5)*AA9 -> 0.6 | AD9: =(F9/1000+0.1)*(Z9/2) -> 0 | AE9: =(F9/1000+0.1)*(AA9/2) -> 0.4125 | AF9: =(Z9/2)*0.1 -> 0 | AG9: =(AA9/2)*0.1 -> 0.0375 | AH9: =Z9 -> 0 | AI9: =AA9 -> 0.75
B10: 5 | C10: Tubulatura Ventilatie | D10: CRD | E10: =C10&"-"&D10&"-"&B10 -> Tubulatura Ventilatie-CRD-5 | F10: 1000 | G10: 300 | H10: 700 | I10: =$F$4&"="&$F10&";"&$G$4&"="&$G10&";"&$H$4&"="&$H10 -> A=1000;B=300;L=700 | J10: buc | K10: 1 | L10: =(2*F10/1000+2*G10/1000)*H10/1000 -> 1.82 | M10: =L10*K10 -> 1.82 | O10: 'Reductie simetrica_asim.'!A1 | P10: =IF((F10+G10)*2>3500,"FLANSA30","FLANSA20") -> FLANSA20 | Q10: =IF(MAX(F10:G10)<=500,"0.6",IF(AND(MAX(F10:G10)>500,MAX(F10:G10)<=1000),"0.8","1.0")) -> 0.8 | R10: =(F10+G10)*4/1000*K10 -> 5.2 | S10: =K10*4*2 -> 8 | T10: =IF(MAX(F10:G10)<=500,M10*4.71,IF(AND(MAX(F10:G10)>500,MAX(F10:G10)<=1000),M10*6.28,M10*7.85)) -> 11.4296 | U10: =((F10+G10)*2*K10)/1000 -> 2.6 | V10: =IF(P10="FLANSA20",K10*4,0) -> 4 | W10: =IF(P10="FLANSA30",K10*4,0) -> 0 | X10: =(((F10+G10)*2)*K10)/350 -> 7.4285714 | Y10: =K10/18 -> 0.055555556 | Z10: =IF(MAX(F10:G10)<800,(H10*K10/2000)*2,0) -> 0 | AA10: =IF(MAX(F10:G10)>=800,(H10*K10/2000)*2,0) -> 0.7 | AB10: =(G10/1000+0.5)*Z10 -> 0 | AC10: =(G10/1000+0.5)*AA10 -> 0.56 | AD10: =(F10/1000+0.1)*(Z10/2) -> 0 | AE10: =(F10/1000+0.1)*(AA10/2) -> 0.385 | AF10: =(Z10/2)*0.1 -> 0 | AG10: =(AA10/2)*0.1 -> 0.035 | AH10: =Z10 -> 0 | AI10: =AA10 -> 0.7
B11: 6 | C11: Tubulatura Ventilatie | D11: CRD | E11: =C11&"-"&D11&"-"&B11 -> Tubulatura Ventilatie-CRD-6 | F11: 1000 | G11: 300 | H11: 666 | I11: =$F$4&"="&$F11&";"&$G$4&"="&$G11&";"&$H$4&"="&$H11 -> A=1000;B=300;L=666 | J11: buc | K11: 4 | L11: =(2*F11/1000+2*G11/1000)*H11/1000 -> 1.7316 | M11: =L11*K11 -> 6.9264 | O11: 'Reductie asimetrica'!A1 | P11: =IF((F11+G11)*2>3500,"FLANSA30","FLANSA20") -> FLANSA20 | Q11: =IF(MAX(F11:G11)<=500,"0.6",IF(AND(MAX(F11:G11)>500,MAX(F11:G11)<=1000),"0.8","1.0")) -> 0.8 | R11: =(F11+G11)*4/1000*K11 -> 20.8 | S11: =K11*4*2 -> 32 | T11: =IF(MAX(F11:G11)<=500,M11*4.71,IF(AND(MAX(F11:G11)>500,MAX(F11:G11)<=1000),M11*6.28,M11*7.85)) -> 43.497792 | U11: =((F11+G11)*2*K11)/1000 -> 10.4 | V11: =IF(P11="FLANSA20",K11*4,0) -> 16 | W11: =IF(P11="FLANSA30",K11*4,0) -> 0 | X11: =(((F11+G11)*2)*K11)/350 -> 29.714286 | Y11: =K11/18 -> 0.22222222 | Z11: =IF(MAX(F11:G11)<800,(H11*K11/2000)*2,0) -> 0 | AA11: =IF(MAX(F11:G11)>=800,(H11*K11/2000)*2,0) -> 2.664 | AB11: =(G11/1000+0.5)*Z11 -> 0 | AC11: =(G11/1000+0.5)*AA11 -> 2.1312 | AD11: =(F11/1000+0.1)*(Z11/2) -> 0 | AE11: =(F11/1000+0.1)*(AA11/2) -> 1.4652 | AF11: =(Z11/2)*0.1 -> 0 | AG11: =(AA11/2)*0.1 -> 0.1332 | AH11: =Z11 -> 0 | AI11: =AA11 -> 2.664
B12: 7 | C12: Tubulatura Ventilatie | D12: CRD | E12: =C12&"-"&D12&"-"&B12 -> Tubulatura Ventilatie-CRD-7 | F12: 900 | G12: 300 | H12: 1250 | I12: =$F$4&"="&$F12&";"&$G$4&"="&$G12&";"&$H$4&"="&$H12 -> A=900;B=300;L=1250 | J12: buc | K12: 6 | L12: =(2*F12/1000+2*G12/1000)*H12/1000 -> 3 | M12: =L12*K12 -> 18 | O12: YAKA!A1 | P12: =IF((F12+G12)*2>3500,"FLANSA30","FLANSA20") -> FLANSA20 | Q12: =IF(MAX(F12:G12)<=500,"0.6",IF(AND(MAX(F12:G12)>500,MAX(F12:G12)<=1000),"0.8","1.0")) -> 0.8 | R12: =(F12+G12)*4/1000*K12 -> 28.8 | S12: =K12*4*2 -> 48 | T12: =IF(MAX(F12:G12)<=500,M12*4.71,IF(AND(MAX(F12:G12)>500,MAX(F12:G12)<=1000),M12*6.28,M12*7.85)) -> 113.04 | U12: =((F12+G12)*2*K12)/1000 -> 14.4 | V12: =IF(P12="FLANSA20",K12*4,0) -> 24 | W12: =IF(P12="FLANSA30",K12*4,0) -> 0 | X12: =(((F12+G12)*2)*K12)/350 -> 41.142857 | Y12: =K12/18 -> 0.33333333 | Z12: =IF(MAX(F12:G12)<800,(H12*K12/2000)*2,0) -> 0 | AA12: =IF(MAX(F12:G12)>=800,(H12*K12/2000)*2,0) -> 7.5 | AB12: =(G12/1000+0.5)*Z12 -> 0 | AC12: =(G12/1000+0.5)*AA12 -> 6 | AD12: =(F12/1000+0.1)*(Z12/2) -> 0 | AE12: =(F12/1000+0.1)*(AA12/2) -> 3.75 | AF12: =(Z12/2)*0.1 -> 0 | AG12: =(AA12/2)*0.1 -> 0.375 | AH12: =Z12 -> 0 | AI12: =AA12 -> 7.5
B13: 8 | C13: Tubulatura Ventilatie | D13: CRD | E13: =C13&"-"&D13&"-"&B13 -> Tubulatura Ventilatie-CRD-8 | F13: 900 | G13: 300 | H13: 900 | I13: =$F$4&"="&$F13&";"&$G$4&"="&$G13&";"&$H$4&"="&$H13 -> A=900;B=300;L=900 | J13: buc | K13: 1 | L13: =(2*F13/1000+2*G13/1000)*H13/1000 -> 2.16 | M13: =L13*K13 -> 2.16 | O13: 'Ramif. bilaterala (2 coturi)'!A1 | P13: =IF((F13+G13)*2>3500,"FLANSA30","FLANSA20") -> FLANSA20 | Q13: =IF(MAX(F13:G13)<=500,"0.6",IF(AND(MAX(F13:G13)>500,MAX(F13:G13)<=1000),"0.8","1.0")) -> 0.8 | R13: =(F13+G13)*4/1000*K13 -> 4.8 | S13: =K13*4*2 -> 8 | T13: =IF(MAX(F13:G13)<=500,M13*4.71,IF(AND(MAX(F13:G13)>500,MAX(F13:G13)<=1000),M13*6.28,M13*7.85)) -> 13.5648 | U13: =((F13+G13)*2*K13)/1000 -> 2.4 | V13: =IF(P13="FLANSA20",K13*4,0) -> 4 | W13: =IF(P13="FLANSA30",K13*4,0) -> 0 | X13: =(((F13+G13)*2)*K13)/350 -> 6.8571429 | Y13: =K13/18 -> 0.055555556 | Z13: =IF(MAX(F13:G13)<800,(H13*K13/2000)*2,0) -> 0 | AA13: =IF(MAX(F13:G13)>=800,(H13*K13/2000)*2,0) -> 0.9 | AB13: =(G13/1000+0.5)*Z13 -> 0 | AC13: =(G13/1000+0.5)*AA13 -> 0.72 | AD13: =(F13/1000+0.1)*(Z13/2) -> 0 | AE13: =(F13/1000+0.1)*(AA13/2) -> 0.45 | AF13: =(Z13/2)*0.1 -> 0 | AG13: =(AA13/2)*0.1 -> 0.045 | AH13: =Z13 -> 0 | AI13: =AA13 -> 0.9
B14: 9 | C14: Tubulatura Ventilatie | D14: CRD | E14: =C14&"-"&D14&"-"&B14 -> Tubulatura Ventilatie-CRD-9 | F14: 900 | G14: 300 | H14: 700 | I14: =$F$4&"="&$F14&";"&$G$4&"="&$G14&";"&$H$4&"="&$H14 -> A=900;B=300;L=700 | J14: buc | K14: 1 | L14: =(2*F14/1000+2*G14/1000)*H14/1000 -> 1.68 | M14: =L14*K14 -> 1.68 | O14: 'Ramif. laterala(cot+canal)'!A1 | P14: =IF((F14+G14)*2>3500,"FLANSA30","FLANSA20") -> FLANSA20 | Q14: =IF(MAX(F14:G14)<=500,"0.6",IF(AND(MAX(F14:G14)>500,MAX(F14:G14)<=1000),"0.8","1.0")) -> 0.8 | R14: =(F14+G14)*4/1000*K14 -> 4.8 | S14: =K14*4*2 -> 8 | T14: =IF(MAX(F14:G14)<=500,M14*4.71,IF(AND(MAX(F14:G14)>500,MAX(F14:G14)<=1000),M14*6.28,M14*7.85)) -> 10.5504 | U14: =((F14+G14)*2*K14)/1000 -> 2.4 | V14: =IF(P14="FLANSA20",K14*4,0) -> 4 | W14: =IF(P14="FLANSA30",K14*4,0) -> 0 | X14: =(((F14+G14)*2)*K14)/350 -> 6.8571429 | Y14: =K14/18 -> 0.055555556 | Z14: =IF(MAX(F14:G14)<800,(H14*K14/2000)*2,0) -> 0 | AA14: =IF(MAX(F14:G14)>=800,(H14*K14/2000)*2,0) -> 0.7 | AB14: =(G14/1000+0.5)*Z14 -> 0 | AC14: =(G14/1000+0.5)*AA14 -> 0.56 | AD14: =(F14/1000+0.1)*(Z14/2) -> 0 | AE14: =(F14/1000+0.1)*(AA14/2) -> 0.35 | AF14: =(Z14/2)*0.1 -> 0 | AG14: =(AA14/2)*0.1 -> 0.035 | AH14: =Z14 -> 0 | AI14: =AA14 -> 0.7
B15: 10 | C15: Tubulatura Ventilatie | D15: CRD | E15: =C15&"-"&D15&"-"&B15 -> Tubulatura Ventilatie-CRD-10 | F15: 900 | G15: 300 | H15: 238 | I15: =$F$4&"="&$F15&";"&$G$4&"="&$G15&";"&$H$4&"="&$H15 -> A=900;B=300;L=238 | J15: buc | K15: 1 | L15: =(2*F15/1000+2*G15/1000)*H15/1000 -> 0.5712 | M15: =L15*K15 -> 0.5712 | O15: 'Ramif. pantalon'!A1 | P15: =IF((F15+G15)*2>3500,"FLANSA30","FLANSA20") -> FLANSA20 | Q15: =IF(MAX(F15:G15)<=500,"0.6",IF(AND(MAX(F15:G15)>500,MAX(F15:G15)<=1000),"0.8","1.0")) -> 0.8 | R15: =(F15+G15)*4/1000*K15 -> 4.8 | S15: =K15*4*2 -> 8 | T15: =IF(MAX(F15:G15)<=500,M15*4.71,IF(AND(MAX(F15:G15)>500,MAX(F15:G15)<=1000),M15*6.28,M15*7.85)) -> 3.587136 | U15: =((F15+G15)*2*K15)/1000 -> 2.4 | V15: =IF(P15="FLANSA20",K15*4,0) -> 4 | W15: =IF(P15="FLANSA30",K15*4,0) -> 0 | X15: =(((F15+G15)*2)*K15)/350 -> 6.8571429 | Y15: =K15/18 -> 0.055555556 | Z15: =IF(MAX(F15:G15)<800,(H15*K15/2000)*2,0) -> 0 | AA15: =IF(MAX(F15:G15)>=800,(H15*K15/2000)*2,0) -> 0.238 | AB15: =(G15/1000+0.5)*Z15 -> 0 | AC15: =(G15/1000+0.5)*AA15 -> 0.1904 | AD15: =(F15/1000+0.1)*(Z15/2) -> 0 | AE15: =(F15/1000+0.1)*(AA15/2) -> 0.119 | AF15: =(Z15/2)*0.1 -> 0 | AG15: =(AA15/2)*0.1 -> 0.0119 | AH15: =Z15 -> 0 | AI15: =AA15 -> 0.238
B16: 11 | C16: Tubulatura Ventilatie | D16: CRD | E16: =C16&"-"&D16&"-"&B16 -> Tubulatura Ventilatie-CRD-11 | F16: 800 | G16: 300 | H16: 1250 | I16: =$F$4&"="&$F16&";"&$G$4&"="&$G16&";"&$H$4&"="&$H16 -> A=800;B=300;L=1250 | J16: buc | K16: 1 | L16: =(2*F16/1000+2*G16/1000)*H16/1000 -> 2.75 | M16: =L16*K16 -> 2.75 | O16: Capac!A1 | P16: =IF((F16+G16)*2>3500,"FLANSA30","FLANSA20") -> FLANSA20 | Q16: =IF(MAX(F16:G16)<=500,"0.6",IF(AND(MAX(F16:G16)>500,MAX(F16:G16)<=1000),"0.8","1.0")) -> 0.8 | R16: =(F16+G16)*4/1000*K16 -> 4.4 | S16: =K16*4*2 -> 8 | T16: =IF(MAX(F16:G16)<=500,M16*4.71,IF(AND(MAX(F16:G16)>500,MAX(F16:G16)<=1000),M16*6.28,M16*7.85)) -> 17.27 | U16: =((F16+G16)*2*K16)/1000 -> 2.2 | V16: =IF(P16="FLANSA20",K16*4,0) -> 4 | W16: =IF(P16="FLANSA30",K16*4,0) -> 0 | X16: =(((F16+G16)*2)*K16)/350 -> 6.2857143 | Y16: =K16/18 -> 0.055555556 | Z16: =IF(MAX(F16:G16)<800,(H16*K16/2000)*2,0) -> 0 | AA16: =IF(MAX(F16:G16)>=800,(H16*K16/2000)*2,0) -> 1.25 | AB16: =(G16/1000+0.5)*Z16 -> 0 | AC16: =(G16/1000+0.5)*AA16 -> 1 | AD16: =(F16/1000+0.1)*(Z16/2) -> 0 | AE16: =(F16/1000+0.1)*(AA16/2) -> 0.5625 | AF16: =(Z16/2)*0.1 -> 0 | AG16: =(AA16/2)*0.1 -> 0.0625 | AH16: =Z16 -> 0 | AI16: =AA16 -> 1.25
B17: 12 | C17: Tubulatura Ventilatie | D17: CRD | E17: =C17&"-"&D17&"-"&B17 -> Tubulatura Ventilatie-CRD-12 | F17: 700 | G17: 300 | H17: 1250 | I17: =$F$4&"="&$F17&";"&$G$4&"="&$G17&";"&$H$4&"="&$H17 -> A=700;B=300;L=1250 | J17: buc | K17: 1 | L17: =(2*F17/1000+2*G17/1000)*H17/1000 -> 2.5 | M17: =L17*K17 -> 2.5 | O17: 'Tubulatura circulara'!A1 | P17: =IF((F17+G17)*2>3500,"FLANSA30","FLANSA20") -> FLANSA20 | Q17: =IF(MAX(F17:G17)<=500,"0.6",IF(AND(MAX(F17:G17)>500,MAX(F17:G17)<=1000),"0.8","1.0")) -> 0.8 | R17: =(F17+G17)*4/1000*K17 -> 4 | S17: =K17*4*2 -> 8 | T17: =IF(MAX(F17:G17)<=500,M17*4.71,IF(AND(MAX(F17:G17)>500,MAX(F17:G17)<=1000),M17*6.28,M17*7.85)) -> 15.7 | U17: =((F17+G17)*2*K17)/1000 -> 2 | V17: =IF(P17="FLANSA20",K17*4,0) -> 4 | W17: =IF(P17="FLANSA30",K17*4,0) -> 0 | X17: =(((F17+G17)*2)*K17)/350 -> 5.7142857 | Y17: =K17/18 -> 0.055555556 | Z17: =IF(MAX(F17:G17)<800,(H17*K17/2000)*2,0) -> 1.25 | AA17: =IF(MAX(F17:G17)>=800,(H17*K17/2000)*2,0) -> 0 | AB17: =(G17/1000+0.5)*Z17 -> 1 | AC17: =(G17/1000+0.5)*AA17 -> 0 | AD17: =(F17/1000+0.1)*(Z17/2) -> 0.5 | AE17: =(F17/1000+0.1)*(AA17/2) -> 0 | AF17: =(Z17/2)*0.1 -> 0.0625 | AG17: =(AA17/2)*0.1 -> 0 | AH17: =Z17 -> 1.25 | AI17: =AA17 -> 0
... B25: 20 | C25: Tubulatura Ventilatie | D25: CRD | E25: =C25&"-"&D25&"-"&B25 -> Tubulatura Ventilatie-CRD-20 | F25: 160 | G25: 300 | H25: 1000 | I25: =$F$4&"="&$F25&";"&$G$4&"="&$G25&";"&$H$4&"="&$H25 -> A=160;B=300;L=1000 | J25: buc | K25: 1 | L25: =(2*F25/1000+2*G25/1000)*H25/1000 -> 0.92 | M25: =L25*K25 -> 0.92 | O25: 'Piesa tip sa PSL'!A1 | P25: =IF((F25+G25)*2>3500,"FLANSA30","FLANSA20") -> FLANSA20 | Q25: =IF(MAX(F25:G25)<=500,"0.6",IF(AND(MAX(F25:G25)>500,MAX(F25:G25)<=1000),"0.8","1.0")) -> 0.6 | R25: =(F25+G25)*4/1000*K25 -> 1.84 | S25: =K25*4*2 -> 8 | T25: =IF(MAX(F25:G25)<=500,M25*4.71,IF(AND(MAX(F25:G25)>500,MAX(F25:G25)<=1000),M25*6.28,M25*7.85)) -> 4.3332 | U25: =((F25+G25)*2*K25)/1000 -> 0.92 | V25: =IF(P25="FLANSA20",K25*4,0) -> 4 | W25: =IF(P25="FLANSA30",K25*4,0) -> 0 | X25: =(((F25+G25)*2)*K25)/350 -> 2.6285714 | Y25: =K25/18 -> 0.055555556 | Z25: =IF(MAX(F25:G25)<800,(H25*K25/2000)*2,0) -> 1 | AA25: =IF(MAX(F25:G25)>=800,(H25*K25/2000)*2,0) -> 0 | AB25: =(G25/1000+0.5)*Z25 -> 0.8 | AC25: =(G25/1000+0.5)*AA25 -> 0 | AD25: =(F25/1000+0.1)*(Z25/2) -> 0.13 | AE25: =(F25/1000+0.1)*(AA25/2) -> 0 | AF25: =(Z25/2)*0.1 -> 0.05 | AG25: =(AA25/2)*0.1 -> 0 | AH25: =Z25 -> 1 | AI25: =AA25 -> 0
D26: CRD | E26: =C26&"-"&D26&"-"&B26 -> -CRD- | I26: =$F$4&"="&$F26&";"&$G$4&"="&$G26&";"&$H$4&"="&$H26 -> A=;B=;L= | J26: buc | L26: =(2*F26/1000+2*G26/1000)*H26/1000 -> 0 | M26: =L26*K26 -> 0 | O26: 'Piesa T TCPL'!A1 | P26: =IF((F26+G26)*2>3500,"FLANSA30","FLANSA20") -> FLANSA20 | Q26: =IF(MAX(F26:G26)<=500,"0.6",IF(AND(MAX(F26:G26)>500,MAX(F26:G26)<=1000),"0.8","1.0")) -> 0.6 | R26: =(F26+G26)*4/1000*K26 -> 0 | S26: =K26*4*2 -> 0 | T26: =IF(MAX(F26:G26)<=500,M26*4.71,IF(AND(MAX(F26:G26)>500,MAX(F26:G26)<=1000),M26*6.28,M26*7.85)) -> 0 | U26: =((F26+G26)*2*K26)/1000 -> 0 | V26: =IF(P26="FLANSA20",K26*4,0) -> 0 | W26: =IF(P26="FLANSA30",K26*4,0) -> 0 | X26: =(((F26+G26)*2)*K26)/350 -> 0 | Y26: =K26/18 -> 0 | Z26: =IF(MAX(F26:G26)<800,(H26*K26/2000)*2,0) -> 0 | AA26: =IF(MAX(F26:G26)>=800,(H26*K26/2000)*2,0) -> 0 | AB26: =(G26/1000+0.5)*Z26 -> 0 | AC26: =(G26/1000+0.5)*AA26 -> 0 | AD26: =(F26/1000+0.1)*(Z26/2) -> 0 | AE26: =(F26/1000+0.1)*(AA26/2) -> 0 | AF26: =(Z26/2)*0.1 -> 0 | AG26: =(AA26/2)*0.1 -> 0 | AH26: =Z26 -> 0 | AI26: =AA26 -> 0
D27: CRD | E27: =C27&"-"&D27&"-"&B27 -> -CRD- | I27: =$F$4&"="&$F27&";"&$G$4&"="&$G27&";"&$H$4&"="&$H27 -> A=;B=;L= | J27: buc | L27: =(2*F27/1000+2*G27/1000)*H27/1000 -> 0 | M27: =L27*K27 -> 0 | O27: 'Conector NPL'!A1 | P27: =IF((F27+G27)*2>3500,"FLANSA30","FLANSA20") -> FLANSA20 | Q27: =IF(MAX(F27:G27)<=500,"0.6",IF(AND(MAX(F27:G27)>500,MAX(F27:G27)<=1000),"0.8","1.0")) -> 0.6 | R27: =(F27+G27)*4/1000*K27 -> 0 | S27: =K27*4*2 -> 0 | T27: =IF(MAX(F27:G27)<=500,M27*4.71,IF(AND(MAX(F27:G27)>500,MAX(F27:G27)<=1000),M27*6.28,M27*7.85)) -> 0 | U27: =((F27+G27)*2*K27)/1000 -> 0 | V27: =IF(P27="FLANSA20",K27*4,0) -> 0 | W27: =IF(P27="FLANSA30",K27*4,0) -> 0 | X27: =(((F27+G27)*2)*K27)/350 -> 0 | Y27: =K27/18 -> 0 | Z27: =IF(MAX(F27:G27)<800,(H27*K27/2000)*2,0) -> 0 | AA27: =IF(MAX(F27:G27)>=800,(H27*K27/2000)*2,0) -> 0 | AB27: =(G27/1000+0.5)*Z27 -> 0 | AC27: =(G27/1000+0.5)*AA27 -> 0 | AD27: =(F27/1000+0.1)*(Z27/2) -> 0 | AE27: =(F27/1000+0.1)*(AA27/2) -> 0 | AF27: =(Z27/2)*0.1 -> 0 | AG27: =(AA27/2)*0.1 -> 0 | AH27: =Z27 -> 0 | AI27: =AA27 -> 0
D28: CRD | E28: =C28&"-"&D28&"-"&B28 -> -CRD- | I28: =$F$4&"="&$F28&";"&$G$4&"="&$G28&";"&$H$4&"="&$H28 -> A=;B=;L= | J28: buc | L28: =(2*F28/1000+2*G28/1000)*H28/1000 -> 0 | M28: =L28*K28 -> 0 | O28: 'Capac EPF'!A1 | P28: =IF((F28+G28)*2>3500,"FLANSA30","FLANSA20") -> FLANSA20 | Q28: =IF(MAX(F28:G28)<=500,"0.6",IF(AND(MAX(F28:G28)>500,MAX(F28:G28)<=1000),"0.8","1.0")) -> 0.6 | R28: =(F28+G28)*4/1000*K28 -> 0 | S28: =K28*4*2 -> 0 | T28: =IF(MAX(F28:G28)<=500,M28*4.71,IF(AND(MAX(F28:G28)>500,MAX(F28:G28)<=1000),M28*6.28,M28*7.85)) -> 0 | U28: =((F28+G28)*2*K28)/1000 -> 0 | V28: =IF(P28="FLANSA20",K28*4,0) -> 0 | W28: =IF(P28="FLANSA30",K28*4,0) -> 0 | X28: =(((F28+G28)*2)*K28)/350 -> 0 | Y28: =K28/18 -> 0 | Z28: =IF(MAX(F28:G28)<800,(H28*K28/2000)*2,0) -> 0 | AA28: =IF(MAX(F28:G28)>=800,(H28*K28/2000)*2,0) -> 0 | AB28: =(G28/1000+0.5)*Z28 -> 0 | AC28: =(G28/1000+0.5)*AA28 -> 0 | AD28: =(F28/1000+0.1)*(Z28/2) -> 0 | AE28: =(F28/1000+0.1)*(AA28/2) -> 0 | AF28: =(Z28/2)*0.1 -> 0 | AG28: =(AA28/2)*0.1 -> 0 | AH28: =Z28 -> 0 | AI28: =AA28 -> 0
D29: CRD | E29: =C29&"-"&D29&"-"&B29 -> -CRD- | I29: =$F$4&"="&$F29&";"&$G$4&"="&$G29&";"&$H$4&"="&$H29 -> A=;B=;L= | J29: buc | L29: =(2*F29/1000+2*G29/1000)*H29/1000 -> 0 | M29: =L29*K29 -> 0 | O29: 'Schimbare sec.concentrica'!A1 | P29: =IF((F29+G29)*2>3500,"FLANSA30","FLANSA20") -> FLANSA20 | Q29: =IF(MAX(F29:G29)<=500,"0.6",IF(AND(MAX(F29:G29)>500,MAX(F29:G29)<=1000),"0.8","1.0")) -> 0.6 | R29: =(F29+G29)*4/1000*K29 -> 0 | S29: =K29*4*2 -> 0 | T29: =IF(MAX(F29:G29)<=500,M29*4.71,IF(AND(MAX(F29:G29)>500,MAX(F29:G29)<=1000),M29*6.28,M29*7.85)) -> 0 | U29: =((F29+G29)*2*K29)/1000 -> 0 | V29: =IF(P29="FLANSA20",K29*4,0) -> 0 | W29: =IF(P29="FLANSA30",K29*4,0) -> 0 | X29: =(((F29+G29)*2)*K29)/350 -> 0 | Y29: =K29/18 -> 0 | Z29: =IF(MAX(F29:G29)<800,(H29*K29/2000)*2,0) -> 0 | AA29: =IF(MAX(F29:G29)>=800,(H29*K29/2000)*2,0) -> 0 | AB29: =(G29/1000+0.5)*Z29 -> 0 | AC29: =(G29/1000+0.5)*AA29 -> 0 | AD29: =(F29/1000+0.1)*(Z29/2) -> 0 | AE29: =(F29/1000+0.1)*(AA29/2) -> 0 | AF29: =(Z29/2)*0.1 -> 0 | AG29: =(AA29/2)*0.1 -> 0 | AH29: =Z29 -> 0 | AI29: =AA29 -> 0
D30: CRD | E30: =C30&"-"&D30&"-"&B30 -> -CRD- | I30: =$F$4&"="&$F30&";"&$G$4&"="&$G30&";"&$H$4&"="&$H30 -> A=;B=;L= | J30: buc | L30: =(2*F30/1000+2*G30/1000)*H30/1000 -> 0 | M30: =L30*K30 -> 0 | O30: 'Schimbare sec.excentrica'!A1 | P30: =IF((F30+G30)*2>3500,"FLANSA30","FLANSA20") -> FLANSA20 | Q30: =IF(MAX(F30:G30)<=500,"0.6",IF(AND(MAX(F30:G30)>500,MAX(F30:G30)<=1000),"0.8","1.0")) -> 0.6 | R30: =(F30+G30)*4/1000*K30 -> 0 | S30: =K30*4*2 -> 0 | T30: =IF(MAX(F30:G30)<=500,M30*4.71,IF(AND(MAX(F30:G30)>500,MAX(F30:G30)<=1000),M30*6.28,M30*7.85)) -> 0 | U30: =((F30+G30)*2*K30)/1000 -> 0 | V30: =IF(P30="FLANSA20",K30*4,0) -> 0 | W30: =IF(P30="FLANSA30",K30*4,0) -> 0 | X30: =(((F30+G30)*2)*K30)/350 -> 0 | Y30: =K30/18 -> 0 | Z30: =IF(MAX(F30:G30)<800,(H30*K30/2000)*2,0) -> 0 | AA30: =IF(MAX(F30:G30)>=800,(H30*K30/2000)*2,0) -> 0 | AB30: =(G30/1000+0.5)*Z30 -> 0 | AC30: =(G30/1000+0.5)*AA30 -> 0 | AD30: =(F30/1000+0.1)*(Z30/2) -> 0 | AE30: =(F30/1000+0.1)*(AA30/2) -> 0 | AF30: =(Z30/2)*0.1 -> 0 | AG30: =(AA30/2)*0.1 -> 0 | AH30: =Z30 -> 0 | AI30: =AA30 -> 0
D31: CRD | E31: =C31&"-"&D31&"-"&B31 -> -CRD- | I31: =$F$4&"="&$F31&";"&$G$4&"="&$G31&";"&$H$4&"="&$H31 -> A=;B=;L= | J31: buc | L31: =(2*F31/1000+2*G31/1000)*H31/1000 -> 0 | M31: =L31*K31 -> 0 | P31: =IF((F31+G31)*2>3500,"FLANSA30","FLANSA20") -> FLANSA20 | Q31: =IF(MAX(F31:G31)<=500,"0.6",IF(AND(MAX(F31:G31)>500,MAX(F31:G31)<=1000),"0.8","1.0")) -> 0.6 | R31: =(F31+G31)*4/1000*K31 -> 0 | S31: =K31*4*2 -> 0 | T31: =IF(MAX(F31:G31)<=500,M31*4.71,IF(AND(MAX(F31:G31)>500,MAX(F31:G31)<=1000),M31*6.28,M31*7.85)) -> 0 | U31: =((F31+G31)*2*K31)/1000 -> 0 | V31: =IF(P31="FLANSA20",K31*4,0) -> 0 | W31: =IF(P31="FLANSA30",K31*4,0) -> 0 | X31: =(((F31+G31)*2)*K31)/350 -> 0 | Y31: =K31/18 -> 0 | Z31: =IF(MAX(F31:G31)<800,(H31*K31/2000)*2,0) -> 0 | AA31: =IF(MAX(F31:G31)>=800,(H31*K31/2000)*2,0) -> 0 | AB31: =(G31/1000+0.5)*Z31 -> 0 | AC31: =(G31/1000+0.5)*AA31 -> 0 | AD31: =(F31/1000+0.1)*(Z31/2) -> 0 | AE31: =(F31/1000+0.1)*(AA31/2) -> 0 | AF31: =(Z31/2)*0.1 -> 0 | AG31: =(AA31/2)*0.1 -> 0 | AH31: =Z31 -> 0 | AI31: =AA31 -> 0
D32: CRD | E32: =C32&"-"&D32&"-"&B32 -> -CRD- | I32: =$F$4&"="&$F32&";"&$G$4&"="&$G32&";"&$H$4&"="&$H32 -> A=;B=;L= | J32: buc | L32: =(2*F32/1000+2*G32/1000)*H32/1000 -> 0 | M32: =L32*K32 -> 0 | P32: =IF((F32+G32)*2>3500,"FLANSA30","FLANSA20") -> FLANSA20 | Q32: =IF(MAX(F32:G32)<=500,"0.6",IF(AND(MAX(F32:G32)>500,MAX(F32:G32)<=1000),"0.8","1.0")) -> 0.6 | R32: =(F32+G32)*4/1000*K32 -> 0 | S32: =K32*4*2 -> 0 | T32: =IF(MAX(F32:G32)<=500,M32*4.71,IF(AND(MAX(F32:G32)>500,MAX(F32:G32)<=1000),M32*6.28,M32*7.85)) -> 0 | U32: =((F32+G32)*2*K32)/1000 -> 0 | V32: =IF(P32="FLANSA20",K32*4,0) -> 0 | W32: =IF(P32="FLANSA30",K32*4,0) -> 0 | X32: =(((F32+G32)*2)*K32)/350 -> 0 | Y32: =K32/18 -> 0 | Z32: =IF(MAX(F32:G32)<800,(H32*K32/2000)*2,0) -> 0 | AA32: =IF(MAX(F32:G32)>=800,(H32*K32/2000)*2,0) -> 0 | AB32: =(G32/1000+0.5)*Z32 -> 0 | AC32: =(G32/1000+0.5)*AA32 -> 0 | AD32: =(F32/1000+0.1)*(Z32/2) -> 0 | AE32: =(F32/1000+0.1)*(AA32/2) -> 0 | AF32: =(Z32/2)*0.1 -> 0 | AG32: =(AA32/2)*0.1 -> 0 | AH32: =Z32 -> 0 | AI32: =AA32 -> 0
D33: CRD | E33: =C33&"-"&D33&"-"&B33 -> -CRD- | I33: =$F$4&"="&$F33&";"&$G$4&"="&$G33&";"&$H$4&"="&$H33 -> A=;B=;L= | J33: buc | L33: =(2*F33/1000+2*G33/1000)*H33/1000 -> 0 | M33: =L33*K33 -> 0 | P33: =IF((F33+G33)*2>3500,"FLANSA30","FLANSA20") -> FLANSA20 | Q33: =IF(MAX(F33:G33)<=500,"0.6",IF(AND(MAX(F33:G33)>500,MAX(F33:G33)<=1000),"0.8","1.0")) -> 0.6 | R33: =(F33+G33)*4/1000*K33 -> 0 | S33: =K33*4*2 -> 0 | T33: =IF(MAX(F33:G33)<=500,M33*4.71,IF(AND(MAX(F33:G33)>500,MAX(F33:G33)<=1000),M33*6.28,M33*7.85)) -> 0 | U33: =((F33+G33)*2*K33)/1000 -> 0 | V33: =IF(P33="FLANSA20",K33*4,0) -> 0 | W33: =IF(P33="FLANSA30",K33*4,0) -> 0 | X33: =(((F33+G33)*2)*K33)/350 -> 0 | Y33: =K33/18 -> 0 | Z33: =IF(MAX(F33:G33)<800,(H33*K33/2000)*2,0) -> 0 | AA33: =IF(MAX(F33:G33)>=800,(H33*K33/2000)*2,0) -> 0 | AB33: =(G33/1000+0.5)*Z33 -> 0 | AC33: =(G33/1000+0.5)*AA33 -> 0 | AD33: =(F33/1000+0.1)*(Z33/2) -> 0 | AE33: =(F33/1000+0.1)*(AA33/2) -> 0 | AF33: =(Z33/2)*0.1 -> 0 | AG33: =(AA33/2)*0.1 -> 0 | AH33: =Z33 -> 0 | AI33: =AA33 -> 0
D34: CRD | E34: =C34&"-"&D34&"-"&B34 -> -CRD- | I34: =$F$4&"="&$F34&";"&$G$4&"="&$G34&";"&$H$4&"="&$H34 -> A=;B=;L= | J34: buc | L34: =(2*F34/1000+2*G34/1000)*H34/1000 -> 0 | M34: =L34*K34 -> 0 | P34: =IF((F34+G34)*2>3500,"FLANSA30","FLANSA20") -> FLANSA20 | Q34: =IF(MAX(F34:G34)<=500,"0.6",IF(AND(MAX(F34:G34)>500,MAX(F34:G34)<=1000),"0.8","1.0")) -> 0.6 | R34: =(F34+G34)*4/1000*K34 -> 0 | S34: =K34*4*2 -> 0 | T34: =IF(MAX(F34:G34)<=500,M34*4.71,IF(AND(MAX(F34:G34)>500,MAX(F34:G34)<=1000),M34*6.28,M34*7.85)) -> 0 | U34: =((F34+G34)*2*K34)/1000 -> 0 | V34: =IF(P34="FLANSA20",K34*4,0) -> 0 | W34: =IF(P34="FLANSA30",K34*4,0) -> 0 | X34: =(((F34+G34)*2)*K34)/350 -> 0 | Y34: =K34/18 -> 0 | Z34: =IF(MAX(F34:G34)<800,(H34*K34/2000)*2,0) -> 0 | AA34: =IF(MAX(F34:G34)>=800,(H34*K34/2000)*2,0) -> 0 | AB34: =(G34/1000+0.5)*Z34 -> 0 | AC34: =(G34/1000+0.5)*AA34 -> 0 | AD34: =(F34/1000+0.1)*(Z34/2) -> 0 | AE34: =(F34/1000+0.1)*(AA34/2) -> 0 | AF34: =(Z34/2)*0.1 -> 0 | AG34: =(AA34/2)*0.1 -> 0 | AH34: =Z34 -> 0 | AI34: =AA34 -> 0
D35: CRD | E35: =C35&"-"&D35&"-"&B35 -> -CRD- | I35: =$F$4&"="&$F35&";"&$G$4&"="&$G35&";"&$H$4&"="&$H35 -> A=;B=;L= | J35: buc | L35: =(2*F35/1000+2*G35/1000)*H35/1000 -> 0 | M35: =L35*K35 -> 0 | P35: =IF((F35+G35)*2>3500,"FLANSA30","FLANSA20") -> FLANSA20 | Q35: =IF(MAX(F35:G35)<=500,"0.6",IF(AND(MAX(F35:G35)>500,MAX(F35:G35)<=1000),"0.8","1.0")) -> 0.6 | R35: =(F35+G35)*4/1000*K35 -> 0 | S35: =K35*4*2 -> 0 | T35: =IF(MAX(F35:G35)<=500,M35*4.71,IF(AND(MAX(F35:G35)>500,MAX(F35:G35)<=1000),M35*6.28,M35*7.85)) -> 0 | U35: =((F35+G35)*2*K35)/1000 -> 0 | V35: =IF(P35="FLANSA20",K35*4,0) -> 0 | W35: =IF(P35="FLANSA30",K35*4,0) -> 0 | X35: =(((F35+G35)*2)*K35)/350 -> 0 | Y35: =K35/18 -> 0 | Z35: =IF(MAX(F35:G35)<800,(H35*K35/2000)*2,0) -> 0 | AA35: =IF(MAX(F35:G35)>=800,(H35*K35/2000)*2,0) -> 0 | AB35: =(G35/1000+0.5)*Z35 -> 0 | AC35: =(G35/1000+0.5)*AA35 -> 0 | AD35: =(F35/1000+0.1)*(Z35/2) -> 0 | AE35: =(F35/1000+0.1)*(AA35/2) -> 0 | AF35: =(Z35/2)*0.1 -> 0 | AG35: =(AA35/2)*0.1 -> 0 | AH35: =Z35 -> 0 | AI35: =AA35 -> 0
D36: CRD | E36: =C36&"-"&D36&"-"&B36 -> -CRD- | I36: =$F$4&"="&$F36&";"&$G$4&"="&$G36&";"&$H$4&"="&$H36 -> A=;B=;L= | J36: buc | L36: =(2*F36/1000+2*G36/1000)*H36/1000 -> 0 | M36: =L36*K36 -> 0 | P36: =IF((F36+G36)*2>3500,"FLANSA30","FLANSA20") -> FLANSA20 | Q36: =IF(MAX(F36:G36)<=500,"0.6",IF(AND(MAX(F36:G36)>500,MAX(F36:G36)<=1000),"0.8","1.0")) -> 0.6 | R36: =(F36+G36)*4/1000*K36 -> 0 | S36: =K36*4*2 -> 0 | T36: =IF(MAX(F36:G36)<=500,M36*4.71,IF(AND(MAX(F36:G36)>500,MAX(F36:G36)<=1000),M36*6.28,M36*7.85)) -> 0 | U36: =((F36+G36)*2*K36)/1000 -> 0 | V36: =IF(P36="FLANSA20",K36*4,0) -> 0 | W36: =IF(P36="FLANSA30",K36*4,0) -> 0 | X36: =(((F36+G36)*2)*K36)/350 -> 0 | Y36: =K36/18 -> 0 | Z36: =IF(MAX(F36:G36)<800,(H36*K36/2000)*2,0) -> 0 | AA36: =IF(MAX(F36:G36)>=800,(H36*K36/2000)*2,0) -> 0 | AB36: =(G36/1000+0.5)*Z36 -> 0 | AC36: =(G36/1000+0.5)*AA36 -> 0 | AD36: =(F36/1000+0.1)*(Z36/2) -> 0 | AE36: =(F36/1000+0.1)*(AA36/2) -> 0 | AF36: =(Z36/2)*0.1 -> 0 | AG36: =(AA36/2)*0.1 -> 0 | AH36: =Z36 -> 0 | AI36: =AA36 -> 0
D37: CRD | E37: =C37&"-"&D37&"-"&B37 -> -CRD- | I37: =$F$4&"="&$F37&";"&$G$4&"="&$G37&";"&$H$4&"="&$H37 -> A=;B=;L= | J37: buc | L37: =(2*F37/1000+2*G37/1000)*H37/1000 -> 0 | M37: =L37*K37 -> 0 | P37: =IF((F37+G37)*2>3500,"FLANSA30","FLANSA20") -> FLANSA20 | Q37: =IF(MAX(F37:G37)<=500,"0.6",IF(AND(MAX(F37:G37)>500,MAX(F37:G37)<=1000),"0.8","1.0")) -> 0.6 | R37: =(F37+G37)*4/1000*K37 -> 0 | S37: =K37*4*2 -> 0 | T37: =IF(MAX(F37:G37)<=500,M37*4.71,IF(AND(MAX(F37:G37)>500,MAX(F37:G37)<=1000),M37*6.28,M37*7.85)) -> 0 | U37: =((F37+G37)*2*K37)/1000 -> 0 | V37: =IF(P37="FLANSA20",K37*4,0) -> 0 | W37: =IF(P37="FLANSA30",K37*4,0) -> 0 | X37: =(((F37+G37)*2)*K37)/350 -> 0 | Y37: =K37/18 -> 0 | Z37: =IF(MAX(F37:G37)<800,(H37*K37/2000)*2,0) -> 0 | AA37: =IF(MAX(F37:G37)>=800,(H37*K37/2000)*2,0) -> 0 | AB37: =(G37/1000+0.5)*Z37 -> 0 | AC37: =(G37/1000+0.5)*AA37 -> 0 | AD37: =(F37/1000+0.1)*(Z37/2) -> 0 | AE37: =(F37/1000+0.1)*(AA37/2) -> 0 | AF37: =(Z37/2)*0.1 -> 0 | AG37: =(AA37/2)*0.1 -> 0 | AH37: =Z37 -> 0 | AI37: =AA37 -> 0
D38: CRD | E38: =C38&"-"&D38&"-"&B38 -> -CRD- | I38: =$F$4&"="&$F38&";"&$G$4&"="&$G38&";"&$H$4&"="&$H38 -> A=;B=;L= | J38: buc | L38: =(2*F38/1000+2*G38/1000)*H38/1000 -> 0 | M38: =L38*K38 -> 0 | P38: =IF((F38+G38)*2>3500,"FLANSA30","FLANSA20") -> FLANSA20 | Q38: =IF(MAX(F38:G38)<=500,"0.6",IF(AND(MAX(F38:G38)>500,MAX(F38:G38)<=1000),"0.8","1.0")) -> 0.6 | R38: =(F38+G38)*4/1000*K38 -> 0 | S38: =K38*4*2 -> 0 | T38: =IF(MAX(F38:G38)<=500,M38*4.71,IF(AND(MAX(F38:G38)>500,MAX(F38:G38)<=1000),M38*6.28,M38*7.85)) -> 0 | U38: =((F38+G38)*2*K38)/1000 -> 0 | V38: =IF(P38="FLANSA20",K38*4,0) -> 0 | W38: =IF(P38="FLANSA30",K38*4,0) -> 0 | X38: =(((F38+G38)*2)*K38)/350 -> 0 | Y38: =K38/18 -> 0 | Z38: =IF(MAX(F38:G38)<800,(H38*K38/2000)*2,0) -> 0 | AA38: =IF(MAX(F38:G38)>=800,(H38*K38/2000)*2,0) -> 0 | AB38: =(G38/1000+0.5)*Z38 -> 0 | AC38: =(G38/1000+0.5)*AA38 -> 0 | AD38: =(F38/1000+0.1)*(Z38/2) -> 0 | AE38: =(F38/1000+0.1)*(AA38/2) -> 0 | AF38: =(Z38/2)*0.1 -> 0 | AG38: =(AA38/2)*0.1 -> 0 | AH38: =Z38 -> 0 | AI38: =AA38 -> 0
D39: CRD | E39: =C39&"-"&D39&"-"&B39 -> -CRD- | I39: =$F$4&"="&$F39&";"&$G$4&"="&$G39&";"&$H$4&"="&$H39 -> A=;B=;L= | J39: buc | L39: =(2*F39/1000+2*G39/1000)*H39/1000 -> 0 | M39: =L39*K39 -> 0 | P39: =IF((F39+G39)*2>3500,"FLANSA30","FLANSA20") -> FLANSA20 | Q39: =IF(MAX(F39:G39)<=500,"0.6",IF(AND(MAX(F39:G39)>500,MAX(F39:G39)<=1000),"0.8","1.0")) -> 0.6 | R39: =(F39+G39)*4/1000*K39 -> 0 | S39: =K39*4*2 -> 0 | T39: =IF(MAX(F39:G39)<=500,M39*4.71,IF(AND(MAX(F39:G39)>500,MAX(F39:G39)<=1000),M39*6.28,M39*7.85)) -> 0 | U39: =((F39+G39)*2*K39)/1000 -> 0 | V39: =IF(P39="FLANSA20",K39*4,0) -> 0 | W39: =IF(P39="FLANSA30",K39*4,0) -> 0 | X39: =(((F39+G39)*2)*K39)/350 -> 0 | Y39: =K39/18 -> 0 | Z39: =IF(MAX(F39:G39)<800,(H39*K39/2000)*2,0) -> 0 | AA39: =IF(MAX(F39:G39)>=800,(H39*K39/2000)*2,0) -> 0 | AB39: =(G39/1000+0.5)*Z39 -> 0 | AC39: =(G39/1000+0.5)*AA39 -> 0 | AD39: =(F39/1000+0.1)*(Z39/2) -> 0 | AE39: =(F39/1000+0.1)*(AA39/2) -> 0 | AF39: =(Z39/2)*0.1 -> 0 | AG39: =(AA39/2)*0.1 -> 0 | AH39: =Z39 -> 0 | AI39: =AA39 -> 0
D40: CRD | E40: =C40&"-"&D40&"-"&B40 -> -CRD- | I40: =$F$4&"="&$F40&";"&$G$4&"="&$G40&";"&$H$4&"="&$H40 -> A=;B=;L= | J40: buc | L40: =(2*F40/1000+2*G40/1000)*H40/1000 -> 0 | M40: =L40*K40 -> 0 | P40: =IF((F40+G40)*2>3500,"FLANSA30","FLANSA20") -> FLANSA20 | Q40: =IF(MAX(F40:G40)<=500,"0.6",IF(AND(MAX(F40:G40)>500,MAX(F40:G40)<=1000),"0.8","1.0")) -> 0.6 | R40: =(F40+G40)*4/1000*K40 -> 0 | S40: =K40*4*2 -> 0 | T40: =IF(MAX(F40:G40)<=500,M40*4.71,IF(AND(MAX(F40:G40)>500,MAX(F40:G40)<=1000),M40*6.28,M40*7.85)) -> 0 | U40: =((F40+G40)*2*K40)/1000 -> 0 | V40: =IF(P40="FLANSA20",K40*4,0) -> 0 | W40: =IF(P40="FLANSA30",K40*4,0) -> 0 | X40: =(((F40+G40)*2)*K40)/350 -> 0 | Y40: =K40/18 -> 0 | Z40: =IF(MAX(F40:G40)<800,(H40*K40/2000)*2,0) -> 0 | AA40: =IF(MAX(F40:G40)>=800,(H40*K40/2000)*2,0) -> 0 | AB40: =(G40/1000+0.5)*Z40 -> 0 | AC40: =(G40/1000+0.5)*AA40 -> 0 | AD40: =(F40/1000+0.1)*(Z40/2) -> 0 | AE40: =(F40/1000+0.1)*(AA40/2) -> 0 | AF40: =(Z40/2)*0.1 -> 0 | AG40: =(AA40/2)*0.1 -> 0 | AH40: =Z40 -> 0 | AI40: =AA40 -> 0
D41: CRD | E41: =C41&"-"&D41&"-"&B41 -> -CRD- | I41: =$F$4&"="&$F41&";"&$G$4&"="&$G41&";"&$H$4&"="&$H41 -> A=;B=;L= | J41: buc | L41: =(2*F41/1000+2*G41/1000)*H41/1000 -> 0 | M41: =L41*K41 -> 0 | P41: =IF((F41+G41)*2>3500,"FLANSA30","FLANSA20") -> FLANSA20 | Q41: =IF(MAX(F41:G41)<=500,"0.6",IF(AND(MAX(F41:G41)>500,MAX(F41:G41)<=1000),"0.8","1.0")) -> 0.6 | R41: =(F41+G41)*4/1000*K41 -> 0 | S41: =K41*4*2 -> 0 | T41: =IF(MAX(F41:G41)<=500,M41*4.71,IF(AND(MAX(F41:G41)>500,MAX(F41:G41)<=1000),M41*6.28,M41*7.85)) -> 0 | U41: =((F41+G41)*2*K41)/1000 -> 0 | V41: =IF(P41="FLANSA20",K41*4,0) -> 0 | W41: =IF(P41="FLANSA30",K41*4,0) -> 0 | X41: =(((F41+G41)*2)*K41)/350 -> 0 | Y41: =K41/18 -> 0 | Z41: =IF(MAX(F41:G41)<800,(H41*K41/2000)*2,0) -> 0 | AA41: =IF(MAX(F41:G41)>=800,(H41*K41/2000)*2,0) -> 0 | AB41: =(G41/1000+0.5)*Z41 -> 0 | AC41: =(G41/1000+0.5)*AA41 -> 0 | AD41: =(F41/1000+0.1)*(Z41/2) -> 0 | AE41: =(F41/1000+0.1)*(AA41/2) -> 0 | AF41: =(Z41/2)*0.1 -> 0 | AG41: =(AA41/2)*0.1 -> 0 | AH41: =Z41 -> 0 | AI41: =AA41 -> 0
D42: CRD | E42: =C42&"-"&D42&"-"&B42 -> -CRD- | I42: =$F$4&"="&$F42&";"&$G$4&"="&$G42&";"&$H$4&"="&$H42 -> A=;B=;L= | J42: buc | L42: =(2*F42/1000+2*G42/1000)*H42/1000 -> 0 | M42: =L42*K42 -> 0 | P42: =IF((F42+G42)*2>3500,"FLANSA30","FLANSA20") -> FLANSA20 | Q42: =IF(MAX(F42:G42)<=500,"0.6",IF(AND(MAX(F42:G42)>500,MAX(F42:G42)<=1000),"0.8","1.0")) -> 0.6 | R42: =(F42+G42)*4/1000*K42 -> 0 | S42: =K42*4*2 -> 0 | T42: =IF(MAX(F42:G42)<=500,M42*4.71,IF(AND(MAX(F42:G42)>500,MAX(F42:G42)<=1000),M42*6.28,M42*7.85)) -> 0 | U42: =((F42+G42)*2*K42)/1000 -> 0 | V42: =IF(P42="FLANSA20",K42*4,0) -> 0 | W42: =IF(P42="FLANSA30",K42*4,0) -> 0 | X42: =(((F42+G42)*2)*K42)/350 -> 0 | Y42: =K42/18 -> 0 | Z42: =IF(MAX(F42:G42)<800,(H42*K42/2000)*2,0) -> 0 | AA42: =IF(MAX(F42:G42)>=800,(H42*K42/2000)*2,0) -> 0 | AB42: =(G42/1000+0.5)*Z42 -> 0 | AC42: =(G42/1000+0.5)*AA42 -> 0 | AD42: =(F42/1000+0.1)*(Z42/2) -> 0 | AE42: =(F42/1000+0.1)*(AA42/2) -> 0 | AF42: =(Z42/2)*0.1 -> 0 | AG42: =(AA42/2)*0.1 -> 0 | AH42: =Z42 -> 0 | AI42: =AA42 -> 0
... D44: CRD | E44: =C44&"-"&D44&"-"&B44 -> -CRD- | I44: =$F$4&"="&$F44&";"&$G$4&"="&$G44&";"&$H$4&"="&$H44 -> A=;B=;L= | J44: buc | L44: =(2*F44/1000+2*G44/1000)*H44/1000 -> 0 | M44: =L44*K44 -> 0 | P44: =IF((F44+G44)*2>3500,"FLANSA30","FLANSA20") -> FLANSA20 | Q44: =IF(MAX(F44:G44)<=500,"0.6",IF(AND(MAX(F44:G44)>500,MAX(F44:G44)<=1000),"0.8","1.0")) -> 0.6 | R44: =(F44+G44)*4/1000*K44 -> 0 | S44: =K44*4*2 -> 0 | T44: =IF(MAX(F44:G44)<=500,M44*4.71,IF(AND(MAX(F44:G44)>500,MAX(F44:G44)<=1000),M44*6.28,M44*7.85)) -> 0 | U44: =((F44+G44)*2*K44)/1000 -> 0 | V44: =IF(P44="FLANSA20",K44*4,0) -> 0 | W44: =IF(P44="FLANSA30",K44*4,0) -> 0 | X44: =(((F44+G44)*2)*K44)/350 -> 0 | Y44: =K44/18 -> 0 | Z44: =IF(MAX(F44:G44)<800,(H44*K44/2000)*2,0) -> 0 | AA44: =IF(MAX(F44:G44)>=800,(H44*K44/2000)*2,0) -> 0 | AB44: =(G44/1000+0.5)*Z44 -> 0 | AC44: =(G44/1000+0.5)*AA44 -> 0 | AD44: =(F44/1000+0.1)*(Z44/2) -> 0 | AE44: =(F44/1000+0.1)*(AA44/2) -> 0 | AF44: =(Z44/2)*0.1 -> 0 | AG44: =(AA44/2)*0.1 -> 0 | AH44: =Z44 -> 0 | AI44: =AA44 -> 0
R47: TOTAL
R48: Flansa [m] | S48: Coltari [buc] | T48: Greutate tabla [kg] | U48: Garnitura etansare [m] | V48: Piulita + Surub M8 [buc] | W48: Piulita + Surub M10 [buc] | X48: Clipsuri [buc] | Y48: Silicon HVAC [buc] | Z48: Piulita expandabila M8 [buc] | AA48: Piulita expandabila M10 [buc] | AB48: Tija filetata M8 [m] | AC48: Tija filetata M10 [m] | AD48: Profil 30x20 [m] | AE48: Profil 41x41 [m] | AF48: Garnitura profil 30x20 [m] | AG48: Garnitura profil 41x41 [m] | AH48: Capac profil 30x20 [buc] | AI48: Capac profil 41x41 [buc]
R51: =SUM(R6:R44) -> 382.88 | S51: =SUM(S6:S44) -> 632 | T51: =SUM(T6:T44) -> 1365.8931 | U51: =SUM(U6:U44) -> 191.44 | V51: =SUM(V6:V44) -> 316 | W51: =SUM(W6:W44) -> 0 | X51: =SUM(X6:X44) -> 546.97143 | Y51: =SUM(Y6:Y44) -> 4.3888889 | ... AI51: =SUM(AI6:AI44) -> 79.99

Sheet Cot rectangular
T2: Confectie | W2: Organe asamblare
B3: Nr. | C3: Sistem | D3: Cod | E3: Eticheta | F3: DIMENSIUNI | K3: Eticheta dimensiuni | L3: UM | M3: Cant | N3: Sunitar | O3: S | Q3: LINK-URI | R3: CONECTARE | S3: GROSIME [mm] | T3: Flansa [m] | U3: Coltari [buc] | V3: Greutate tabla [kg] | W3: Garnitura etansare [m] | X3: Piulita + Surub M8 [buc] | Y3: Piulita + Surub M10 [buc] | Z3: Clipsuri [buc] | AA3: Silicon HVAC [buc]
F4: A1 | G4: A2 | H4: B | I4: R | J4: < | Q4: 'Canal drept'!A1
F5: mm | G5: mm | H5: mm | I5: mm | J5: (°) | N5: m2 | O5: m2 | Q5: 'Cot rectangular'!A1
B6: 1 | C6: Tubulatura Ventilatie | D6: CR | E6: =CONCATENATE(C6,"-",D6,"-",B6) -> Tubulatura Ventilatie-CR-1 | F6: 200 | G6: 200 | H6: 300 | I6: 100 | J6: 45 | K6: =CONCATENATE(F$4,"=",F6,"; ",G$4,"=",G6,"; ",H$4,"=",H6,"; ",I$4,"=",I6,"; ",J$4,"=",J6) -> A1=200; A2 =200; B=300; R =100; < =45 | L6: buc | M6: 4 | N6: =((2*(F6+I6)*(G6+I6)+H6*PI()*(I6+MAX(F6,G6)/2))*J6/90)/10^6 -> 0.18424778 | O6: =M6*N6 -> 0.73699112 | Q6: 'Cot rectangular drept'!A1 | R6: =IF((F6+H6)*2>3500,"FLANSA30","FLANSA20") -> FLANSA20 | S6: =IF(MAX(F6:H6)<=500,"0.6",IF(AND(MAX(F6:H6)>500,MAX(F6:H6)<=1000),"0.8","1.0")) -> 0.6 | T6: =(((F6+H6)*2/1000)+((G6+H6)*2/1000))*M6 -> 8 | U6: =M6*4*2 -> 32 | V6: =IF(MAX(F6:H6)<=500,O6*4.71,IF(AND(MAX(F6:H6)>500,MAX(F6:H6)<=1000),O6*6.28,O6*7.85)) -> 3.4712282 | W6: =((F6+H6)*2+(G6+H6)*2)/1000/2*M6 -> 4 | X6: =IF(R6="FLANSA20",M6*4,0) -> 16 | Y6: =IF(R6="FLANSA30",M6*4,0) -> 0 | Z6: =((F6+H6)/350+(G6+H6)/350)*M6 -> 11.428571 | AA6: =M6/18 -> 0.22222222
B7: 2 | C7: Tubulatura Ventilatie | D7: CR | E7: =CONCATENATE(C7,"-",D7,"-",B7) -> Tubulatura Ventilatie-CR-2 | F7: 900 | G7: 900 | H7: 300 | I7: 500 | J7: 90 | K7: =CONCATENATE(F$4,"=",F7,"; ",G$4,"=",G7,"; ",H$4,"=",H7,"; ",I$4,"=",I7,"; ",J$4,"=",J7) -> A1=900; A2 =900; B=300; R =500; < =90 | L7: buc | M7: 1 | N7: =((2*(F7+I7)*(G7+I7)+H7*PI()*(I7+MAX(F7,G7)/2))*J7/90)/10^6 -> 4.8153539 | O7: =M7*N7 -> 4.8153539 | Q7: 'Cot rectangular cu dirijori'!A1 | R7: =IF((F7+H7)*2>3500,"FLANSA30","FLANSA20") -> FLANSA20 | S7: =IF(MAX(F7:H7)<=500,"0.6",IF(AND(MAX(F7:H7)>500,MAX(F7:H7)<=1000),"0.8","1.0")) -> 0.8 | T7: =(((F7+H7)*2/1000)+((G7+H7)*2/1000))*M7 -> 4.8 | U7: =M7*4*2 -> 8 | V7: =IF(MAX(F7:H7)<=500,O7*4.71,IF(AND(MAX(F7:H7)>500,MAX(F7:H7)<=1000),O7*6.28,O7*7.85)) -> 30.240423 | W7: =((F7+H7)*2+(G7+H7)*2)/1000/2*M7 -> 2.4 | X7: =IF(R7="FLANSA20",M7*4,0) -> 4 | Y7: =IF(R7="FLANSA30",M7*4,0) -> 0 | Z7: =((F7+H7)/350+(G7+H7)/350)*M7 -> 6.8571429 | AA7: =M7/18 -> 0.055555556
C8: Tubulatura Ventilatie | D8: CR | E8: =CONCATENATE(C8,"-",D8,"-",B8) -> Tubulatura Ventilatie-CR- | F8: 650 | G8: 650 | H8: 300 | I8: 150 | J8: 90 | K8: =CONCATENATE(F$4,"=",F8,"; ",G$4,"=",G8,"; ",H$4,"=",H8,"; ",I$4,"=",I8,"; ",J$4,"=",J8) -> A1=650; A2 =650; B=300; R =150; < =90 | L8: buc | M8: 1 | N8: =((2*(F8+I8)*(G8+I8)+H8*PI()*(I8+MAX(F8,G8)/2))*J8/90)/10^6 -> 1.727677 | O8: =M8*N8 -> 1.727677 | Q8: Teu!A1 | R8: =IF((F8+H8)*2>3500,"FLANSA30","FLANSA20") -> FLANSA20 | S8: =IF(MAX(F8:H8)<=500,"0.6",IF(AND(MAX(F8:H8)>500,MAX(F8:H8)<=1000),"0.8","1.0")) -> 0.8 | T8: =(((F8+H8)*2/1000)+((G8+H8)*2/1000))*M8 -> 3.8 | U8: =M8*4*2 -> 8 | V8: =IF(MAX(F8:H8)<=500,O8*4.71,IF(AND(MAX(F8:H8)>500,MAX(F8:H8)<=1000),O8*6.28,O8*7.85)) -> 10.849811 | W8: =((F8+H8)*2+(G8+H8)*2)/1000/2*M8 -> 1.9 | X8: =IF(R8="FLANSA20",M8*4,0) -> 4 | Y8: =IF(R8="FLANSA30",M8*4,0) -> 0 | Z8: =((F8+H8)/350+(G8+H8)/350)*M8 -> 5.4285714 | AA8: =M8/18 -> 0.055555556
D9: CR | E9: =CONCATENATE(C9,"-",D9,"-",B9) -> -CR- | K9: =CONCATENATE(F$4,"=",F9,"; ",G$4,"=",G9,"; ",H$4,"=",H9,"; ",I$4,"=",I9,"; ",J$4,"=",J9) -> A1=; A2 =; B=; R =; < = | L9: buc | N9: =((2*(F9+I9)*(G9+I9)+H9*PI()*(I9+MAX(F9,G9)/2))*J9/90)/10^6 -> 0 | O9: =M9*N9 -> 0 | Q9: 'Piesa de deviatie (etaj)'!A1 | R9: =IF((F9+H9)*2>3500,"FLANSA30","FLANSA20") -> FLANSA20 | S9: =IF(MAX(F9:H9)<=500,"0.6",IF(AND(MAX(F9:H9)>500,MAX(F9:H9)<=1000),"0.8","1.0")) -> 0.6 | T9: =(((F9+H9)*2/1000)+((G9+H9)*2/1000))*M9 -> 0 | U9: =M9*4*2 -> 0 | V9: =IF(MAX(F9:H9)<=500,O9*4.71,IF(AND(MAX(F9:H9)>500,MAX(F9:H9)<=1000),O9*6.28,O9*7.85)) -> 0 | W9: =((F9+H9)*2+(G9+H9)*2)/1000/2*M9 -> 0 | X9: =IF(R9="FLANSA20",M9*4,0) -> 0 | Y9: =IF(R9="FLANSA30",M9*4,0) -> 0 | Z9: =((F9+H9)/350+(G9+H9)/350)*M9 -> 0 | AA9: =M9/18 -> 0
D10: CR | E10: =CONCATENATE(C10,"-",D10,"-",B10) -> -CR- | K10: =CONCATENATE(F$4,"=",F10,"; ",G$4,"=",G10,"; ",H$4,"=",H10,"; ",I$4,"=",I10,"; ",J$4,"=",J10) -> A1=; A2 =; B=; R =; < = | L10: buc | N10: =((2*(F10+I10)*(G10+I10)+H10*PI()*(I10+MAX(F10,G10)/2))*J10/90)/10^6 -> 0 | O10: =M10*N10 -> 0 | Q10: 'Reductie simetrica_asim.'!A1 | R10: =IF((F10+H10)*2>3500,"FLANSA30","FLANSA20") -> FLANSA20 | S10: =IF(MAX(F10:H10)<=500,"0.6",IF(AND(MAX(F10:H10)>500,MAX(F10:H10)<=1000),"0.8","1.0")) -> 0.6 | T10: =(((F10+H10)*2/1000)+((G10+H10)*2/1000))*M10 -> 0 | U10: =M10*4*2 -> 0 | V10: =IF(MAX(F10:H10)<=500,O10*4.71,IF(AND(MAX(F10:H10)>500,MAX(F10:H10)<=1000),O10*6.28,O10*7.85)) -> 0 | W10: =((F10+H10)*2+(G10+H10)*2)/1000/2*M10 -> 0 | X10: =IF(R10="FLANSA20",M10*4,0) -> 0 | Y10: =IF(R10="FLANSA30",M10*4,0) -> 0 | Z10: =((F10+H10)/350+(G10+H10)/350)*M10 -> 0 | AA10: =M10/18 -> 0
D11: CR | E11: =CONCATENATE(C11,"-",D11,"-",B11) -> -CR- | K11: =CONCATENATE(F$4,"=",F11,"; ",G$4,"=",G11,"; ",H$4,"=",H11,"; ",I$4,"=",I11,"; ",J$4,"=",J11) -> A1=; A2 =; B=; R =; < = | L11: buc | N11: =((2*(F11+I11)*(G11+I11)+H11*PI()*(I11+MAX(F11,G11)/2))*J11/90)/10^6 -> 0 | O11: =M11*N11 -> 0 | Q11: 'Reductie asimetrica'!A1 | R11: =IF((F11+H11)*2>3500,"FLANSA30","FLANSA20") -> FLANSA20 | S11: =IF(MAX(F11:H11)<=500,"0.6",IF(AND(MAX(F11:H11)>500,MAX(F11:H11)<=1000),"0.8","1.0")) -> 0.6 | T11: =(((F11+H11)*2/1000)+((G11+H11)*2/1000))*M11 -> 0 | U11: =M11*4*2 -> 0 | V11: =IF(MAX(F11:H11)<=500,O11*4.71,IF(AND(MAX(F11:H11)>500,MAX(F11:H11)<=1000),O11*6.28,O11*7.85)) -> 0 | W11: =((F11+H11)*2+(G11+H11)*2)/1000/2*M11 -> 0 | X11: =IF(R11="FLANSA20",M11*4,0) -> 0 | Y11: =IF(R11="FLANSA30",M11*4,0) -> 0 | Z11: =((F11+H11)/350+(G11+H11)/350)*M11 -> 0 | AA11: =M11/18 -> 0
D12: CR | E12: =CONCATENATE(C12,"-",D12,"-",B12) -> -CR- | K12: =CONCATENATE(F$4,"=",F12,"; ",G$4,"=",G12,"; ",H$4,"=",H12,"; ",I$4,"=",I12,"; ",J$4,"=",J12) -> A1=; A2 =; B=; R =; < = | L12: buc | N12: =((2*(F12+I12)*(G12+I12)+H12*PI()*(I12+MAX(F12,G12)/2))*J12/90)/10^6 -> 0 | O12: =M12*N12 -> 0 | Q12: YAKA!A1 | R12: =IF((F12+H12)*2>3500,"FLANSA30","FLANSA20") -> FLANSA20 | S12: =IF(MAX(F12:H12)<=500,"0.6",IF(AND(MAX(F12:H12)>500,MAX(F12:H12)<=1000),"0.8","1.0")) -> 0.6 | T12: =(((F12+H12)*2/1000)+((G12+H12)*2/1000))*M12 -> 0 | U12: =M12*4*2 -> 0 | V12: =IF(MAX(F12:H12)<=500,O12*4.71,IF(AND(MAX(F12:H12)>500,MAX(F12:H12)<=1000),O12*6.28,O12*7.85)) -> 0 | W12: =((F12+H12)*2+(G12+H12)*2)/1000/2*M12 -> 0 | X12: =IF(R12="FLANSA20",M12*4,0) -> 0 | Y12: =IF(R12="FLANSA30",M12*4,0) -> 0 | Z12: =((F12+H12)/350+(G12+H12)/350)*M12 -> 0 | AA12: =M12/18 -> 0
D13: CR | E13: =CONCATENATE(C13,"-",D13,"-",B13) -> -CR- | K13: =CONCATENATE(F$4,"=",F13,"; ",G$4,"=",G13,"; ",H$4,"=",H13,"; ",I$4,"=",I13,"; ",J$4,"=",J13) -> A1=; A2 =; B=; R =; < = | L13: buc | N13: =((2*(F13+I13)*(G13+I13)+H13*PI()*(I13+MAX(F13,G13)/2))*J13/90)/10^6 -> 0 | O13: =M13*N13 -> 0 | Q13: 'Ramif. bilaterala (2 coturi)'!A1 | R13: =IF((F13+H13)*2>3500,"FLANSA30","FLANSA20") -> FLANSA20 | S13: =IF(MAX(F13:H13)<=500,"0.6",IF(AND(MAX(F13:H13)>500,MAX(F13:H13)<=1000),"0.8","1.0")) -> 0.6 | T13: =(((F13+H13)*2/1000)+((G13+H13)*2/1000))*M13 -> 0 | U13: =M13*4*2 -> 0 | V13: =IF(MAX(F13:H13)<=500,O13*4.71,IF(AND(MAX(F13:H13)>500,MAX(F13:H13)<=1000),O13*6.28,O13*7.85)) -> 0 | W13: =((F13+H13)*2+(G13+H13)*2)/1000/2*M13 -> 0 | X13: =IF(R13="FLANSA20",M13*4,0) -> 0 | Y13: =IF(R13="FLANSA30",M13*4,0) -> 0 | Z13: =((F13+H13)/350+(G13+H13)/350)*M13 -> 0 | AA13: =M13/18 -> 0
D14: CR | E14: =CONCATENATE(C14,"-",D14,"-",B14) -> -CR- | K14: =CONCATENATE(F$4,"=",F14,"; ",G$4,"=",G14,"; ",H$4,"=",H14,"; ",I$4,"=",I14,"; ",J$4,"=",J14) -> A1=; A2 =; B=; R =; < = | L14: buc | N14: =((2*(F14+I14)*(G14+I14)+H14*PI()*(I14+MAX(F14,G14)/2))*J14/90)/10^6 -> 0 | O14: =M14*N14 -> 0 | Q14: 'Ramif. laterala(cot+canal)'!A1 | R14: =IF((F14+H14)*2>3500,"FLANSA30","FLANSA20") -> FLANSA20 | S14: =IF(MAX(F14:H14)<=500,"0.6",IF(AND(MAX(F14:H14)>500,MAX(F14:H14)<=1000),"0.8","1.0")) -> 0.6 | T14: =(((F14+H14)*2/1000)+((G14+H14)*2/1000))*M14 -> 0 | U14: =M14*4*2 -> 0 | V14: =IF(MAX(F14:H14)<=500,O14*4.71,IF(AND(MAX(F14:H14)>500,MAX(F14:H14)<=1000),O14*6.28,O14*7.85)) -> 0 | W14: =((F14+H14)*2+(G14+H14)*2)/1000/2*M14 -> 0 | X14: =IF(R14="FLANSA20",M14*4,0) -> 0 | Y14: =IF(R14="FLANSA30",M14*4,0) -> 0 | Z14: =((F14+H14)/350+(G14+H14)/350)*M14 -> 0 | AA14: =M14/18 -> 0
D15: CR | E15: =CONCATENATE(C15,"-",D15,"-",B15) -> -CR- | K15: =CONCATENATE(F$4,"=",F15,"; ",G$4,"=",G15,"; ",H$4,"=",H15,"; ",I$4,"=",I15,"; ",J$4,"=",J15) -> A1=; A2 =; B=; R =; < = | L15: buc | N15: =((2*(F15+I15)*(G15+I15)+H15*PI()*(I15+MAX(F15,G15)/2))*J15/90)/10^6 -> 0 | O15: =M15*N15 -> 0 | Q15: 'Ramif. pantalon'!A1 | R15: =IF((F15+H15)*2>3500,"FLANSA30","FLANSA20") -> FLANSA20 | S15: =IF(MAX(F15:H15)<=500,"0.6",IF(AND(MAX(F15:H15)>500,MAX(F15:H15)<=1000),"0.8","1.0")) -> 0.6 | T15: =(((F15+H15)*2/1000)+((G15+H15)*2/1000))*M15 -> 0 | U15: =M15*4*2 -> 0 | V15: =IF(MAX(F15:H15)<=500,O15*4.71,IF(AND(MAX(F15:H15)>500,MAX(F15:H15)<=1000),O15*6.28,O15*7.85)) -> 0 | W15: =((F15+H15)*2+(G15+H15)*2)/1000/2*M15 -> 0 | X15: =IF(R15="FLANSA20",M15*4,0) -> 0 | Y15: =IF(R15="FLANSA30",M15*4,0) -> 0 | Z15: =((F15+H15)/350+(G15+H15)/350)*M15 -> 0 | AA15: =M15/18 -> 0
D16: CR | E16: =CONCATENATE(C16,"-",D16,"-",B16) -> -CR- | K16: =CONCATENATE(F$4,"=",F16,"; ",G$4,"=",G16,"; ",H$4,"=",H16,"; ",I$4,"=",I16,"; ",J$4,"=",J16) -> A1=; A2 =; B=; R =; < = | L16: buc | N16: =((2*(F16+I16)*(G16+I16)+H16*PI()*(I16+MAX(F16,G16)/2))*J16/90)/10^6 -> 0 | O16: =M16*N16 -> 0 | Q16: Capac!A1 | R16: =IF((F16+H16)*2>3500,"FLANSA30","FLANSA20") -> FLANSA20 | S16: =IF(MAX(F16:H16)<=500,"0.6",IF(AND(MAX(F16:H16)>500,MAX(F16:H16)<=1000),"0.8","1.0")) -> 0.6 | T16: =(((F16+H16)*2/1000)+((G16+H16)*2/1000))*M16 -> 0 | U16: =M16*4*2 -> 0 | V16: =IF(MAX(F16:H16)<=500,O16*4.71,IF(AND(MAX(F16:H16)>500,MAX(F16:H16)<=1000),O16*6.28,O16*7.85)) -> 0 | W16: =((F16+H16)*2+(G16+H16)*2)/1000/2*M16 -> 0 | X16: =IF(R16="FLANSA20",M16*4,0) -> 0 | Y16: =IF(R16="FLANSA30",M16*4,0) -> 0 | Z16: =((F16+H16)/350+(G16+H16)/350)*M16 -> 0 | AA16: =M16/18 -> 0
D17: CR | E17: =CONCATENATE(C17,"-",D17,"-",B17) -> -CR- | K17: =CONCATENATE(F$4,"=",F17,"; ",G$4,"=",G17,"; ",H$4,"=",H17,"; ",I$4,"=",I17,"; ",J$4,"=",J17) -> A1=; A2 =; B=; R =; < = | L17: buc | N17: =((2*(F17+I17)*(G17+I17)+H17*PI()*(I17+MAX(F17,G17)/2))*J17/90)/10^6 -> 0 | O17: =M17*N17 -> 0 | Q17: 'Tubulatura circulara'!A1 | R17: =IF((F17+H17)*2>3500,"FLANSA30","FLANSA20") -> FLANSA20 | S17: =IF(MAX(F17:H17)<=500,"0.6",IF(AND(MAX(F17:H17)>500,MAX(F17:H17)<=1000),"0.8","1.0")) -> 0.6 | T17: =(((F17+H17)*2/1000)+((G17+H17)*2/1000))*M17 -> 0 | U17: =M17*4*2 -> 0 | V17: =IF(MAX(F17:H17)<=500,O17*4.71,IF(AND(MAX(F17:H17)>500,MAX(F17:H17)<=1000),O17*6.28,O17*7.85)) -> 0 | W17: =((F17+H17)*2+(G17+H17)*2)/1000/2*M17 -> 0 | X17: =IF(R17="FLANSA20",M17*4,0) -> 0 | Y17: =IF(R17="FLANSA30",M17*4,0) -> 0 | Z17: =((F17+H17)/350+(G17+H17)/350)*M17 -> 0 | AA17: =M17/18 -> 0
D18: CR | E18: =CONCATENATE(C18,"-",D18,"-",B18) -> -CR- | K18: =CONCATENATE(F$4,"=",F18,"; ",G$4,"=",G18,"; ",H$4,"=",H18,"; ",I$4,"=",I18,"; ",J$4,"=",J18) -> A1=; A2 =; B=; R =; < = | L18: buc | N18: =((2*(F18+I18)*(G18+I18)+H18*PI()*(I18+MAX(F18,G18)/2))*J18/90)/10^6 -> 0 | O18: =M18*N18 -> 0 | Q18: 'Cot BFL90'!A1 | R18: =IF((F18+H18)*2>3500,"FLANSA30","FLANSA20") -> FLANSA20 | S18: =IF(MAX(F18:H18)<=500,"0.6",IF(AND(MAX(F18:H18)>500,MAX(F18:H18)<=1000),"0.8","1.0")) -> 0.6 | T18: =(((F18+H18)*2/1000)+((G18+H18)*2/1000))*M18 -> 0 | U18: =M18*4*2 -> 0 | V18: =IF(MAX(F18:H18)<=500,O18*4.71,IF(AND(MAX(F18:H18)>500,MAX(F18:H18)<=1000),O18*6.28,O18*7.85)) -> 0 | W18: =((F18+H18)*2+(G18+H18)*2)/1000/2*M18 -> 0 | X18: =IF(R18="FLANSA20",M18*4,0) -> 0 | Y18: =IF(R18="FLANSA30",M18*4,0) -> 0 | Z18: =((F18+H18)/350+(G18+H18)/350)*M18 -> 0 | AA18: =M18/18 -> 0
